Workbook

Sheet Summary
A1: WEEK 43 2026 — FOR MANAGEMENT & PRODUCTION SUMMARY
A2: ="Generated "&TEXT(TODAY(),"mmmm d, yyyy")&" | Source: SHIPMENTS & Prod Load tabs" -> Generated October 19, 2026 | Source: SHIPMENTS & Prod Load tabs
A4: SHIPMENT PIPELINE OVERVIEW
A5: Metric | B5: Value
A6: Total Open Shipment Orders | B6: =COUNTA(SHIPMENTS!A7:A483) -> 53
A7: Total CBM (all orders) | B7: =SUM(SHIPMENTS!F7:F483) -> 556.22599
A8: Average CBM per Order | B8: =B7/B6 -> 10.49483
A9: Orders with Confirmed Target Completion Date | B9: =COUNT(SHIPMENTS!G7:G483) -> 34
A10: Orders Pending Target Date ("TBA") | B10: =COUNTIF(SHIPMENTS!G7:G483,"TBA") -> 6
A11: Orders Flagged "Waiting" (booking/materials/order) | B11: {=SUMPRODUCT(--ISNUMBER(SEARCH("waiting",SHIPMENTS!H7:H483)))} -> 1
A12: Orders Mentioning Fumigation Requirement | B12: {=SUMPRODUCT(--ISNUMBER(SEARCH("fumigation",SHIPMENTS!H7:H483)))} -> 16
A13: of which still Pending (not marked DONE) | B13: {=SUMPRODUCT(ISNUMBER(SEARCH("fumigation",SHIPMENTS!H7:H483))*(1-ISNUMBER(SEARCH("done",SHIPMENTS!H7:H483))))} -> 15
A14: Average Order Age (days) | B14: =AVERAGE(SHIPMENTS!AT7:AT483) -> 57.202497
A15: Oldest Order Age (days) | B15: =MAX(SHIPMENTS!AT7:AT483) -> 345.61759
A16: Orders Aged Over 90 Days | B16: =COUNTIF(SHIPMENTS!AT7:AT483,">90") -> 12
A17: Average Completion Rate per SO (all open orders) | B17: =AVERAGE(SHIPMENTS!AU7:AU483) -> 0.36853381
A18: Orders Ready to Ship (100% Complete) | B18: =COUNTIF(SHIPMENTS!AU7:AU483,">=0.999") -> 11
A19: Orders Below 50% Complete (at risk) | B19: =COUNTIF(SHIPMENTS!AU7:AU483,"<0.5") -> 36
A20: SO's ALMOST READY (Near Completion, Not Yet 100%)
A21: Min % Complete (inclusive) | B21: 0.8 | C21: Max % Complete (exclusive, below Ready) | D21: 0.999
A22: SO # | B22: Customer/Destination | C22: Completion % | D22: Target Completion
A23: {=IFERROR(INDEX(SHIPMENTS!$A$7:$A$483,_xlfn.AGGREGATE(15,6,(ROW(SHIPMENTS!$AU$7:$AU$483)-ROW(SHIPMENTS!$AU$7)+1)/((SHIPMENTS!$AU$7:$AU$483>=$B$21)*(SHIPMENTS!$AU$7:$AU$483<$D$21)),ROW()-22)),"")} -> 8641 | B23: {=IFERROR(INDEX(SHIPMENTS!$B$7:$B$483,_xlfn.AGGREGATE(15,6,(ROW(SHIPMENTS!$AU$7:$AU$483)-ROW(SHIPMENTS!$AU$7)+1)/((SHIPMENTS!$AU$7:$AU$483>=$B$21)*(SHIPMENTS!$AU$7:$AU$483<$D$21)),ROW()-22)),"")} -> 41700-CANADA BSAUNAS BACKLOG | C23: {=IFERROR(INDEX(SHIPMENTS!$AU$7:$AU$483,_xlfn.AGGREGATE(15,6,(ROW(SHIPMENTS!$AU$7:$AU$483)-ROW(SHIPMENTS!$AU$7)+1)/((SHIPMENTS!$AU$7:$AU$483>=$B$21)*(SHIPMENTS!$AU$7:$AU$483<$D$21)),ROW()-22)),"")} -> 0.85333333 | D23: {=IFERROR(INDEX(SHIPMENTS!$G$7:$G$483,_xlfn.AGGREGATE(15,6,(ROW(SHIPMENTS!$AU$7:$AU$483)-ROW(SHIPMENTS!$AU$7)+1)/((SHIPMENTS!$AU$7:$AU$483>=$B$21)*(SHIPMENTS!$AU$7:$AU$483<$D$21)),ROW()-22)),"")} -> 46315
A24: {=IFERROR(INDEX(SHIPMENTS!$A$7:$A$483,_xlfn.AGGREGATE(15,6,(ROW(SHIPMENTS!$AU$7:$AU$483)-ROW(SHIPMENTS!$AU$7)+1)/((SHIPMENTS!$AU$7:$AU$483>=$B$21)*(SHIPMENTS!$AU$7:$AU$483<$D$21)),ROW()-22)),"")} -> 4781 | B24: {=IFERROR(INDEX(SHIPMENTS!$B$7:$B$483,_xlfn.AGGREGATE(15,6,(ROW(SHIPMENTS!$AU$7:$AU$483)-ROW(SHIPMENTS!$AU$7)+1)/((SHIPMENTS!$AU$7:$AU$483>=$B$21)*(SHIPMENTS!$AU$7:$AU$483<$D$21)),ROW()-22)),"")} -> 41700-CANADA BSAUNAS BACKLOG | C24: {=IFERROR(INDEX(SHIPMENTS!$AU$7:$AU$483,_xlfn.AGGREGATE(15,6,(ROW(SHIPMENTS!$AU$7:$AU$483)-ROW(SHIPMENTS!$AU$7)+1)/((SHIPMENTS!$AU$7:$AU$483>=$B$21)*(SHIPMENTS!$AU$7:$AU$483<$D$21)),ROW()-22)),"")} -> 0.95 | D24: {=IFERROR(INDEX(SHIPMENTS!$G$7:$G$483,_xlfn.AGGREGATE(15,6,(ROW(SHIPMENTS!$AU$7:$AU$483)-ROW(SHIPMENTS!$AU$7)+1)/((SHIPMENTS!$AU$7:$AU$483>=$B$21)*(SHIPMENTS!$AU$7:$AU$483<$D$21)),ROW()-22)),"")} -> 0
A25: {=IFERROR(INDEX(SHIPMENTS!$A$7:$A$483,_xlfn.AGGREGATE(15,6,(ROW(SHIPMENTS!$AU$7:$AU$483)-ROW(SHIPMENTS!$AU$7)+1)/((SHIPMENTS!$AU$7:$AU$483>=$B$21)*(SHIPMENTS!$AU$7:$AU$483<$D$21)),ROW()-22)),"")} | B25: {=IFERROR(INDEX(SHIPMENTS!$B$7:$B$483,_xlfn.AGGREGATE(15,6,(ROW(SHIPMENTS!$AU$7:$AU$483)-ROW(SHIPMENTS!$AU$7)+1)/((SHIPMENTS!$AU$7:$AU$483>=$B$21)*(SHIPMENTS!$AU$7:$AU$483<$D$21)),ROW()-22)),"")} | C25: {=IFERROR(INDEX(SHIPMENTS!$AU$7:$AU$483,_xlfn.AGGREGATE(15,6,(ROW(SHIPMENTS!$AU$7:$AU$483)-ROW(SHIPMENTS!$AU$7)+1)/((SHIPMENTS!$AU$7:$AU$483>=$B$21)*(SHIPMENTS!$AU$7:$AU$483<$D$21)),ROW()-22)),"")} | D25: {=IFERROR(INDEX(SHIPMENTS!$G$7:$G$483,_xlfn.AGGREGATE(15,6,(ROW(SHIPMENTS!$AU$7:$AU$483)-ROW(SHIPMENTS!$AU$7)+1)/((SHIPMENTS!$AU$7:$AU$483>=$B$21)*(SHIPMENTS!$AU$7:$AU$483<$D$21)),ROW()-22)),"")}
A26: {=IFERROR(INDEX(SHIPMENTS!$A$7:$A$483,_xlfn.AGGREGATE(15,6,(ROW(SHIPMENTS!$AU$7:$AU$483)-ROW(SHIPMENTS!$AU$7)+1)/((SHIPMENTS!$AU$7:$AU$483>=$B$21)*(SHIPMENTS!$AU$7:$AU$483<$D$21)),ROW()-22)),"")} | B26: {=IFERROR(INDEX(SHIPMENTS!$B$7:$B$483,_xlfn.AGGREGATE(15,6,(ROW(SHIPMENTS!$AU$7:$AU$483)-ROW(SHIPMENTS!$AU$7)+1)/((SHIPMENTS!$AU$7:$AU$483>=$B$21)*(SHIPMENTS!$AU$7:$AU$483<$D$21)),ROW()-22)),"")} | C26: {=IFERROR(INDEX(SHIPMENTS!$AU$7:$AU$483,_xlfn.AGGREGATE(15,6,(ROW(SHIPMENTS!$AU$7:$AU$483)-ROW(SHIPMENTS!$AU$7)+1)/((SHIPMENTS!$AU$7:$AU$483>=$B$21)*(SHIPMENTS!$AU$7:$AU$483<$D$21)),ROW()-22)),"")} | D26: {=IFERROR(INDEX(SHIPMENTS!$G$7:$G$483,_xlfn.AGGREGATE(15,6,(ROW(SHIPMENTS!$AU$7:$AU$483)-ROW(SHIPMENTS!$AU$7)+1)/((SHIPMENTS!$AU$7:$AU$483>=$B$21)*(SHIPMENTS!$AU$7:$AU$483<$D$21)),ROW()-22)),"")}
A27: {=IFERROR(INDEX(SHIPMENTS!$A$7:$A$483,_xlfn.AGGREGATE(15,6,(ROW(SHIPMENTS!$AU$7:$AU$483)-ROW(SHIPMENTS!$AU$7)+1)/((SHIPMENTS!$AU$7:$AU$483>=$B$21)*(SHIPMENTS!$AU$7:$AU$483<$D$21)),ROW()-22)),"")} | B27: {=IFERROR(INDEX(SHIPMENTS!$B$7:$B$483,_xlfn.AGGREGATE(15,6,(ROW(SHIPMENTS!$AU$7:$AU$483)-ROW(SHIPMENTS!$AU$7)+1)/((SHIPMENTS!$AU$7:$AU$483>=$B$21)*(SHIPMENTS!$AU$7:$AU$483<$D$21)),ROW()-22)),"")} | C27: {=IFERROR(INDEX(SHIPMENTS!$AU$7:$AU$483,_xlfn.AGGREGATE(15,6,(ROW(SHIPMENTS!$AU$7:$AU$483)-ROW(SHIPMENTS!$AU$7)+1)/((SHIPMENTS!$AU$7:$AU$483>=$B$21)*(SHIPMENTS!$AU$7:$AU$483<$D$21)),ROW()-22)),"")} | D27: {=IFERROR(INDEX(SHIPMENTS!$G$7:$G$483,_xlfn.AGGREGATE(15,6,(ROW(SHIPMENTS!$AU$7:$AU$483)-ROW(SHIPMENTS!$AU$7)+1)/((SHIPMENTS!$AU$7:$AU$483>=$B$21)*(SHIPMENTS!$AU$7:$AU$483<$D$21)),ROW()-22)),"")}
A28: {=IFERROR(INDEX(SHIPMENTS!$A$7:$A$483,_xlfn.AGGREGATE(15,6,(ROW(SHIPMENTS!$AU$7:$AU$483)-ROW(SHIPMENTS!$AU$7)+1)/((SHIPMENTS!$AU$7:$AU$483>=$B$21)*(SHIPMENTS!$AU$7:$AU$483<$D$21)),ROW()-22)),"")} | B28: {=IFERROR(INDEX(SHIPMENTS!$B$7:$B$483,_xlfn.AGGREGATE(15,6,(ROW(SHIPMENTS!$AU$7:$AU$483)-ROW(SHIPMENTS!$AU$7)+1)/((SHIPMENTS!$AU$7:$AU$483>=$B$21)*(SHIPMENTS!$AU$7:$AU$483<$D$21)),ROW()-22)),"")} | C28: {=IFERROR(INDEX(SHIPMENTS!$AU$7:$AU$483,_xlfn.AGGREGATE(15,6,(ROW(SHIPMENTS!$AU$7:$AU$483)-ROW(SHIPMENTS!$AU$7)+1)/((SHIPMENTS!$AU$7:$AU$483>=$B$21)*(SHIPMENTS!$AU$7:$AU$483<$D$21)),ROW()-22)),"")} | D28: {=IFERROR(INDEX(SHIPMENTS!$G$7:$G$483,_xlfn.AGGREGATE(15,6,(ROW(SHIPMENTS!$AU$7:$AU$483)-ROW(SHIPMENTS!$AU$7)+1)/((SHIPMENTS!$AU$7:$AU$483>=$B$21)*(SHIPMENTS!$AU$7:$AU$483<$D$21)),ROW()-22)),"")}
A29: {=IFERROR(INDEX(SHIPMENTS!$A$7:$A$483,_xlfn.AGGREGATE(15,6,(ROW(SHIPMENTS!$AU$7:$AU$483)-ROW(SHIPMENTS!$AU$7)+1)/((SHIPMENTS!$AU$7:$AU$483>=$B$21)*(SHIPMENTS!$AU$7:$AU$483<$D$21)),ROW()-22)),"")} | B29: {=IFERROR(INDEX(SHIPMENTS!$B$7:$B$483,_xlfn.AGGREGATE(15,6,(ROW(SHIPMENTS!$AU$7:$AU$483)-ROW(SHIPMENTS!$AU$7)+1)/((SHIPMENTS!$AU$7:$AU$483>=$B$21)*(SHIPMENTS!$AU$7:$AU$483<$D$21)),ROW()-22)),"")} | C29: {=IFERROR(INDEX(SHIPMENTS!$AU$7:$AU$483,_xlfn.AGGREGATE(15,6,(ROW(SHIPMENTS!$AU$7:$AU$483)-ROW(SHIPMENTS!$AU$7)+1)/((SHIPMENTS!$AU$7:$AU$483>=$B$21)*(SHIPMENTS!$AU$7:$AU$483<$D$21)),ROW()-22)),"")} | D29: {=IFERROR(INDEX(SHIPMENTS!$G$7:$G$483,_xlfn.AGGREGATE(15,6,(ROW(SHIPMENTS!$AU$7:$AU$483)-ROW(SHIPMENTS!$AU$7)+1)/((SHIPMENTS!$AU$7:$AU$483>=$B$21)*(SHIPMENTS!$AU$7:$AU$483<$D$21)),ROW()-22)),"")}
A30: {=IFERROR(INDEX(SHIPMENTS!$A$7:$A$483,_xlfn.AGGREGATE(15,6,(ROW(SHIPMENTS!$AU$7:$AU$483)-ROW(SHIPMENTS!$AU$7)+1)/((SHIPMENTS!$AU$7:$AU$483>=$B$21)*(SHIPMENTS!$AU$7:$AU$483<$D$21)),ROW()-22)),"")} | B30: {=IFERROR(INDEX(SHIPMENTS!$B$7:$B$483,_xlfn.AGGREGATE(15,6,(ROW(SHIPMENTS!$AU$7:$AU$483)-ROW(SHIPMENTS!$AU$7)+1)/((SHIPMENTS!$AU$7:$AU$483>=$B$21)*(SHIPMENTS!$AU$7:$AU$483<$D$21)),ROW()-22)),"")} | C30: {=IFERROR(INDEX(SHIPMENTS!$AU$7:$AU$483,_xlfn.AGGREGATE(15,6,(ROW(SHIPMENTS!$AU$7:$AU$483)-ROW(SHIPMENTS!$AU$7)+1)/((SHIPMENTS!$AU$7:$AU$483>=$B$21)*(SHIPMENTS!$AU$7:$AU$483<$D$21)),ROW()-22)),"")} | D30: {=IFERROR(INDEX(SHIPMENTS!$G$7:$G$483,_xlfn.AGGREGATE(15,6,(ROW(SHIPMENTS!$AU$7:$AU$483)-ROW(SHIPMENTS!$AU$7)+1)/((SHIPMENTS!$AU$7:$AU$483>=$B$21)*(SHIPMENTS!$AU$7:$AU$483<$D$21)),ROW()-22)),"")}
A31: {=IFERROR(INDEX(SHIPMENTS!$A$7:$A$483,_xlfn.AGGREGATE(15,6,(ROW(SHIPMENTS!$AU$7:$AU$483)-ROW(SHIPMENTS!#REF!)+1)/((SHIPMENTS!$AU$7:$AU$483>=$B$21)*(SHIPMENTS!$AU$7:$AU$483<$D$21)),ROW()-22)),"")} | B31: {=IFERROR(INDEX(SHIPMENTS!$B$7:$B$483,_xlfn.AGGREGATE(15,6,(ROW(SHIPMENTS!$AU$7:$AU$483)-ROW(SHIPMENTS!#REF!)+1)/((SHIPMENTS!$AU$7:$AU$483>=$B$21)*(SHIPMENTS!$AU$7:$AU$483<$D$21)),ROW()-22)),"")} | C31: {=IFERROR(INDEX(SHIPMENTS!$AU$7:$AU$483,_xlfn.AGGREGATE(15,6,(ROW(SHIPMENTS!$AU$7:$AU$483)-ROW(SHIPMENTS!#REF!)+1)/((SHIPMENTS!$AU$7:$AU$483>=$B$21)*(SHIPMENTS!$AU$7:$AU$483<$D$21)),ROW()-22)),"")} | D31: {=IFERROR(INDEX(SHIPMENTS!$G$7:$G$483,_xlfn.AGGREGATE(15,6,(ROW(SHIPMENTS!$AU$7:$AU$483)-ROW(SHIPMENTS!#REF!)+1)/((SHIPMENTS!$AU$7:$AU$483>=$B$21)*(SHIPMENTS!$AU$7:$AU$483<$D$21)),ROW()-22)),"")}
A32: {=IFERROR(INDEX(SHIPMENTS!$A$7:$A$483,_xlfn.AGGREGATE(15,6,(ROW(SHIPMENTS!$AU$7:$AU$483)-ROW(SHIPMENTS!#REF!)+1)/((SHIPMENTS!$AU$7:$AU$483>=$B$21)*(SHIPMENTS!$AU$7:$AU$483<$D$21)),ROW()-22)),"")} | B32: {=IFERROR(INDEX(SHIPMENTS!$B$7:$B$483,_xlfn.AGGREGATE(15,6,(ROW(SHIPMENTS!$AU$7:$AU$483)-ROW(SHIPMENTS!#REF!)+1)/((SHIPMENTS!$AU$7:$AU$483>=$B$21)*(SHIPMENTS!$AU$7:$AU$483<$D$21)),ROW()-22)),"")} | C32: {=IFERROR(INDEX(SHIPMENTS!$AU$7:$AU$483,_xlfn.AGGREGATE(15,6,(ROW(SHIPMENTS!$AU$7:$AU$483)-ROW(SHIPMENTS!#REF!)+1)/((SHIPMENTS!$AU$7:$AU$483>=$B$21)*(SHIPMENTS!$AU$7:$AU$483<$D$21)),ROW()-22)),"")} | D32: {=IFERROR(INDEX(SHIPMENTS!$G$7:$G$483,_xlfn.AGGREGATE(15,6,(ROW(SHIPMENTS!$AU$7:$AU$483)-ROW(SHIPMENTS!#REF!)+1)/((SHIPMENTS!$AU$7:$AU$483>=$B$21)*(SHIPMENTS!$AU$7:$AU$483<$D$21)),ROW()-22)),"")}
A33: {=IFERROR(INDEX(SHIPMENTS!$A$7:$A$483,_xlfn.AGGREGATE(15,6,(ROW(SHIPMENTS!$AU$7:$AU$483)-ROW(SHIPMENTS!#REF!)+1)/((SHIPMENTS!$AU$7:$AU$483>=$B$21)*(SHIPMENTS!$AU$7:$AU$483<$D$21)),ROW()-22)),"")} | B33: {=IFERROR(INDEX(SHIPMENTS!$B$7:$B$483,_xlfn.AGGREGATE(15,6,(ROW(SHIPMENTS!$AU$7:$AU$483)-ROW(SHIPMENTS!#REF!)+1)/((SHIPMENTS!$AU$7:$AU$483>=$B$21)*(SHIPMENTS!$AU$7:$AU$483<$D$21)),ROW()-22)),"")} | C33: {=IFERROR(INDEX(SHIPMENTS!$AU$7:$AU$483,_xlfn.AGGREGATE(15,6,(ROW(SHIPMENTS!$AU$7:$AU$483)-ROW(SHIPMENTS!#REF!)+1)/((SHIPMENTS!$AU$7:$AU$483>=$B$21)*(SHIPMENTS!$AU$7:$AU$483<$D$21)),ROW()-22)),"")} | D33: {=IFERROR(INDEX(SHIPMENTS!$G$7:$G$483,_xlfn.AGGREGATE(15,6,(ROW(SHIPMENTS!$AU$7:$AU$483)-ROW(SHIPMENTS!#REF!)+1)/((SHIPMENTS!$AU$7:$AU$483>=$B$21)*(SHIPMENTS!$AU$7:$AU$483<$D$21)),ROW()-22)),"")}
A36: CBM BY CARGO TYPE
A37: Cargo Type | B37: # Orders | C37: CBM
A38: 1X20 | B38: =COUNTIF(SHIPMENTS!I7:I483,"1X20") -> 5 | C38: =SUMIF(SHIPMENTS!I7:I483,"1X20",SHIPMENTS!F7:F483) -> 86.536094
A39: 1X40HC | B39: =COUNTIF(SHIPMENTS!I7:I483,"1X40HC") -> 5 | C39: =SUMIF(SHIPMENTS!I7:I483,"1X40HC",SHIPMENTS!F7:F483) -> 389.16752
A40: LCL | B40: =COUNTIF(SHIPMENTS!I7:I483,"LCL") -> 6 | C40: =SUMIF(SHIPMENTS!I7:I483,"LCL",SHIPMENTS!F7:F483) -> 5.1886
A41: AIR | B41: =COUNTIF(SHIPMENTS!I7:I483,"AIR") -> 2 | C41: =SUMIF(SHIPMENTS!I7:I483,"AIR",SHIPMENTS!F7:F483) -> 0.13403
A42: Unspecified / TBA | B42: =B6-SUM(B38:B41) -> 35 | C42: =B7-SUM(C38:C41) -> 75.19975
A44: PRODUCTION CAPACITY & LOAD (Prod Load tab, as of Jul 24)
...

Sheet Wkly Shipped CBM & LT
A1: Weekly Shipped CBM & Leadtime Report
A2: Source: 'SO Monitoring' tab (STATUS = SHIPPED, ACTUAL LOADING date)
D3: =AVERAGE(D5:D43) -> 78.916019 | E3: =AVERAGE(E5:E43) -> 41.159105
A4: Week # | B4: Week Start | C4: Week End | D4: Shipped CBM | E4: Avg Leadtime (days) | F4: SO#
A5: =_xlfn.ISOWEEKNUM(B5) -> 2 | B5: =DATE(2026,1,5) -> 46027 | C5: =B5+6 -> 46033 | D5: 26.27617 | E5: 31.623188 | F5: 4834, 4865, 4991, 5210, 5221, 5249, 5361, 5370, 5391, 5397, 5478
A6: =_xlfn.ISOWEEKNUM(B6) -> 3 | B6: =$B$5+7*(ROW()-5) -> 46034 | C6: =B6+6 -> 46040 | D6: 137.948 | E6: 44.291892 | F6: 4645, 5001, 4781, 4849, 4969, 5146, 5177, 5247, 5283, 5390, 5398, 5457, 5491, 5449, 5355
A7: =_xlfn.ISOWEEKNUM(B7) -> 4 | B7: =$B$5+7*(ROW()-5) -> 46041 | C7: =B7+6 -> 46047 | D7: 36.07193 | E7: 44.828571 | F7: 4079, 4767, 5165, 5221, 5258, 5259, 5337, 5445, 5475, 5570, 5578, 5585, 5608, 5536, 5504
A8: =_xlfn.ISOWEEKNUM(B8) -> 5 | B8: =$B$5+7*(ROW()-5) -> 46048 | C8: =B8+6 -> 46054 | D8: 49.30314 | E8: 21.87037 | F8: 5098, 5277, 5278, 5280, 5286, 5428, 5430, 5489, 5488, 5495, 5507, 5539, 5543, 5547, 5565, 5576, 5584, 5508, 5619, 5668, 5670, 5678, 5681, 5683, 5725, 5751, 5757
A9: =_xlfn.ISOWEEKNUM(B9) -> 6 | B9: =$B$5+7*(ROW()-5) -> 46055 | C9: =B9+6 -> 46061 | D9: 32.88263 | E9: 23.90625 | F9: 5412, 5424, 5437, 5581, 5602, 5613, 5673, 5721, 5759, 5492, 5770, 5827, 5844, 5849, 5912
A10: =_xlfn.ISOWEEKNUM(B10) -> 7 | B10: =$B$5+7*(ROW()-5) -> 46062 | C10: =B10+6 -> 46068 | D10: 106.37939 | E10: 58.649275 | F10: 4605, 4975, 4972, 5160, 5458, 5456, 5578, 5699, 6029
A11: =_xlfn.ISOWEEKNUM(B11) -> 8 | B11: =$B$5+7*(ROW()-5) -> 46069 | C11: =B11+6 -> 46075 | D11: 16.32906 | E11: 19.408163 | F11: 5589, 5785, 5803, 5804, 5620, 5890, 5921, 5991, 6026, 6051, 6079, 6078, 6048, 6125, 6134, 6149
A12: =_xlfn.ISOWEEKNUM(B12) -> 9 | B12: =$B$5+7*(ROW()-5) -> 46076 | C12: =B12+6 -> 46082 | D12: 128.19569 | E12: 39.792079 | F12: 4852, 5013, 5290, 5412, 5437, 5581, 5588, 5508, 5665, 5673, 5723, 5741, 5758, 5761, 5842, 5845, 5919, 5933, 5998, 6004, 6025, 6087, 6096, 6115, 6142, 6155, 6194, 6193, 6205, 6236, 6242
A13: =_xlfn.ISOWEEKNUM(B13) -> 10 | B13: =$B$5+7*(ROW()-5) -> 46083 | C13: =B13+6 -> 46089 | D13: 104.32249 | E13: 50.277419 | F13: 9205, 4129, 5432, 5805, 5836, 5840, 5406, 5887, 5942, 5975, 6016, 6049, 6185, 6189, 5913, 6278, 6281, 6348, 6352
A14: =_xlfn.ISOWEEKNUM(B14) -> 11 | B14: =$B$5+7*(ROW()-5) -> 46090 | C14: =B14+6 -> 46096 | D14: 114.62271 | E14: 75.980843 | F14: 4235, 4603, CONTAINER 4, 4943, 5198, 5333, 5338, 5394, 5405, 5427, 5601, 5661, 5749, 5839, 6020, 6247, 6265, 6061, 6322, 6345, 6353, 6394
A15: =_xlfn.ISOWEEKNUM(B15) -> 12 | B15: =$B$5+7*(ROW()-5) -> 46097 | C15: =B15+6 -> 46103 | D15: 8.70062 | E15: 32.285714 | F15: 5941, 6407, 6216, 6461, 6506, 6514
A16: =_xlfn.ISOWEEKNUM(B16) -> 13 | B16: =$B$5+7*(ROW()-5) -> 46104 | C16: =B16+6 -> 46110 | D16: 241.48992 | E16: 45.904494 | F16: 9051, 9250, 5437, 5442, 5524, 5534, 5546, 5673, 5677, 5697, 6136, 6188, 6246, 6336, 6180, 6339, 6333, 6289, 6291, 6305, 6344, 5917, 6415, 6418, 6447, 6515, 6528, 6598, 6600
A17: =_xlfn.ISOWEEKNUM(B17) -> 14 | B17: =$B$5+7*(ROW()-5) -> 46111 | C17: =B17+6 -> 46117 | D17: 112.90324 | E17: 47.286307 | F17: CONTAINER 5, CONTAINER 4, 5488, 5509, 5730, 6141, 6168, 6167, 6197, 6212, 6240, 6342, 6358, 6376, 6379, 6380, 6397, 6426, 6686, 6485, 6483, 6481, 6475, 6489, 6498, 6512, 6566, 6586, 6605, 6624, 6628, 6633, 6648
... A38: =_xlfn.ISOWEEKNUM(B38) -> 35 | B38: =$B$5+7*(ROW()-5) -> 46258 | C38: =B38+6 -> 46264 | D38: 38.88353 | E38: 18.809524 | F38: 6346, 8093, 8269, 8285, 8309, 8307, 8319, 8336, 8369, 8419, 8445, 8421, 8447, 8423, 8417, 8459, 8476
A39: =_xlfn.ISOWEEKNUM(B39) -> 36 | B39: =$B$5+7*(ROW()-5) -> 46265 | C39: =B39+6 -> 46271 | D39: =78.0240700000001+0.057 -> 78.08107 | E39: 23.164557 | F39: 6979, 8084, 8428, 8461, 8522, 8525, 8563, 8584, 8527, 8595, 8546, 8643, 8655
A40: =_xlfn.ISOWEEKNUM(B40) -> 37 | B40: =$B$5+7*(ROW()-5) -> 46272 | C40: =B40+6 -> 46278 | D40: =77.38615+2+0.001 -> 79.38715 | E40: 82.191358 | F40: 6646, 7114, 7426, 7491, 8047, 8294, 8517, 8610, 8645, 8694
A41: =_xlfn.ISOWEEKNUM(B41) -> 38 | B41: =$B$5+7*(ROW()-5) -> 46279 | C41: =B41+6 -> 46285 | D41: =82.9638+0.6 -> 83.5638 | E41: 48.261538 | F41: 6863, 7919, 8643, 8667, 8678, 8483, 8727, 8804, 8785, 8857
A42: =_xlfn.ISOWEEKNUM(B42) -> 39 | B42: =$B$5+7*(ROW()-5) -> 46286 | C42: =B42+6 -> 46292 | D42: 114.8096 | E42: 47.22 | F42: 6863, 7919, 8643, 8667, 8678, 8483, 8727, 8804, 8785, 8857
A43: =_xlfn.ISOWEEKNUM(B43) -> 40 | B43: =$B$5+7*(ROW()-5) -> 46293 | C43: =B43+6 -> 46299 | D43: =162.068-0.15 -> 161.918 | E43: 41.62
A44: =_xlfn.ISOWEEKNUM(B44) -> 41 | B44: =$B$5+7*(ROW()-5) -> 46300 | C44: =B44+6 -> 46306 | D44: 98.92 | E44: 33.5
A45: 42 | B45: =$B$5+7*(ROW()-5) -> 46307 | C45: =B45+6 -> 46313 | D45: 80.7229 | E45: 53.947368

Sheet SHIPMENTS
A1: WEEKLY SHIPMENT SCHEDULES | AN1: 40 | AO1: 41 | AP1: 42
A2: WEEK 43 | R2: =SUM(R7:R483) -> 1087 | S2: =SUM(S7:S483) -> 566 | T2: =SUM(T7:T483) -> 28748 | U2: =SUM(U7:U483) -> 764 | V2: =SUM(V7:V483) -> 60 | W2: =SUM(W7:W483) -> 7518 | X2: =SUM(X7:X483) -> 1948 | Y2: =SUM(Y7:Y483) -> 908 | AA2: =SUM(AA7:AA483) -> 40.60097 | AB2: =SUM(AB7:AB483) -> 74.310815 | AC2: =SUM(AC7:AC483) -> 2.02018 | AD2: =SUM(AD7:AD483) -> 11.582955 | AE2: =SUM(AE7:AE483) -> 0 | AF2: =SUM(AF7:AF483) -> 5.08191 | AG2: =SUM(AG7:AG483) -> 0.07616 | AH2: =SUM(AH7:AH483) -> 0
A4: DETAILS | J4: COMPLETION RATE (as of October 16) | R4: PRODUCT QTY | AA4: WOOD REQUIREMENTS | AJ4: SF - PO/LTL COMPLETION RATE | AS4: =AVERAGE(AS7:AS59) -> 37.323529 | AT4: =AVERAGE(AT7:AT59) -> 57.202497 | AU4: OVERALL
A5: SO # | B5: CUST. CODE-DESTINATION | C5: ITEMS | D5: CBM as of 10/9 | E5: ITEMS | F5: TOTAL CBM | G5: ESTIMATED TARGET COMPLETION | H5: REMARKS | I5: CARGO TYPE | J5: Control Unit Assembly | K5: Heaters Assembly | L5: Wood Working P1-Accessories | M5: Wood Working Plant 1-Doors | N5: Wood Working Plant 2 | O5: =SUM(O7:O994) -> 62 | P5: TARGET WEEK | Q5: Sunday & Holiday | R5: Controls | S5: Heaters | T5: Wooden Accessories | U5: Doors | V5: Sauna Rooms | W5: Panels/Timbers | X5: Spare parts | Y5: Sauna Stones | AA5: 4RM03-D1 Cedar 1st Class | AB5: 4RM03-D3 Cedar with Knots | AC5: 4RM01-A1 Aspen 1st Class | AD5: 4RM01-A3 Aspen with Stain | AE5: 4RM02-P1 Pine 1st Class | AF5: 4RM02-P3 Pine with knots | AG5: 4RM16-B Basswood | AH5: 4RM05-S3 Spruce | AJ5: TOOL & DIE | AK5: STONE PROCESSING | AL5: METAL STAMPING | AM5: PRE-ASSY | AN5: ELECTRICAL ASSEMBLY | AO5: MACHINING P2 - DOORS | AP5: MACHINING P2 - SAUNA FAB | AR5: SO Received Date | AS5: SO-TD LT (Days) | AT5: Order Age (Days) | AU5: AVG COMPLETION %
A7: 7728 | B7: 52300-KUWAIT | C7: 15 UNITS SAUNA ROOMS (0908MS-9sr IR Cedar & 1111RS-6sr IR Cedar), CONTROLS, HEATERS, WOODEN ACCESSORIES, DOORS & PANELS | D7: 3.75 | E7: =C7 -> 15 UNITS SAUNA ROOMS (0908MS-9sr IR Cedar & 1111RS-6sr IR Cedar), CONTROLS, HEATERS, WOODEN ACCESSORIES, DOORS & PANELS | F7: 27.2 | H7: note: crate fumigation - 8/14 note: waiting for booking | I7: 1X40 | J7: 1 | K7: 1 | L7: 1 | M7: n/a | N7: 1 | O7: 15 | R7: =IF(VLOOKUP($A7,Items!$A$5:$J$1000,8,0)=0," ",VLOOKUP($A7,Items!$A$5:$J$1000,8,0)) -> 25 | S7: =IF(VLOOKUP($A7,Items!$A$5:$J$1000,3,0)=0," ",VLOOKUP($A7,Items!$A$5:$J$1000,3,0)) -> 13 | T7: =IF(VLOOKUP($A7,Items!$A$5:$J$1000,7,0)=0," ",VLOOKUP($A7,Items!$A$5:$J$1000,7,0)) -> 85 | U7: =IF(VLOOKUP($A7,Items!$A$5:$J$1000,2,0)=0," ",VLOOKUP($A7,Items!$A$5:$J$1000,2,0)) -> 3 | V7: =IF(VLOOKUP($A7,Items!$A$5:$J$1000,9,0)=0," ",VLOOKUP($A7,Items!$A$5:$J$1000,9,0)) -> 15 | W7: =IF(VLOOKUP($A7,Items!$A$5:$J$1000,4,0)=0," ",VLOOKUP($A7,Items!$A$5:$J$1000,4,0)) -> 388 | X7: =IF(VLOOKUP($A7,Items!$A$5:$J$1000,6,0)=0," ",VLOOKUP($A7,Items!$A$5:$J$1000,6,0)) -> 23 | Y7: =IF(VLOOKUP($A7,Items!$A$5:$J$1000,5,0)=0," ",VLOOKUP($A7,Items!$A$5:$J$1000,5,0)) -> 2 | AA7: =IF(VLOOKUP($A7,Wood!$A$5:$W$1000,16,0)=0," ",VLOOKUP($A7,Wood!$A$5:$W$1000,16,0)) -> 2.80916 | AB7: =IF(VLOOKUP($A7,Wood!$A$5:$W$1000,17,0)=0," ",VLOOKUP($A7,Wood!$A$5:$W$1000,17,0)) -> 10.93903 | AC7: =IF(VLOOKUP($A7,Wood!$A$5:$W$1000,18,0)=0," ",VLOOKUP($A7,Wood!$A$5:$W$1000,18,0)) -> 0.008 | AD7: =IF(VLOOKUP($A7,Wood!$A$5:$W$1000,19,0)=0," ",VLOOKUP($A7,Wood!$A$5:$W$1000,19,0)) -> 0.006745 | AE7: =IF(VLOOKUP($A7,Wood!$A$5:$W$1000,20,0)=0," ",VLOOKUP($A7,Wood!$A$5:$W$1000,20,0)) | AF7: =IF(VLOOKUP($A7,Wood!$A$5:$W$1000,21,0)=0," ",VLOOKUP($A7,Wood!$A$5:$W$1000,21,0)) | AG7: =IF(VLOOKUP($A7,Wood!$A$5:$W$1000,22,0)=0," ",VLOOKUP($A7,Wood!$A$5:$W$1000,22,0)) | AH7: =IF(VLOOKUP($A7,Wood!$A$5:$W$1000,23,0)=0," ",VLOOKUP($A7,Wood!$A$5:$W$1000,23,0)) | AN7: 1 | AO7: n/a | AP7: 1 | AR7: 46192 | AT7: =NOW()-AR7 -> 122.61759 | AU7: =IFERROR(AVERAGE(J7:N7,AJ7:AP7),"n/a") -> 1
A8: 7626 | B8: 58300-SAUDI ARABIA | C8: HEATERS, CONTROLS, SPARE PARTS & WOODEN ACCESSORIES | D8: 1.1396 | E8: =C8 -> HEATERS, CONTROLS, SPARE PARTS & WOODEN ACCESSORIES | F8: =SUM(D8:D10) -> 2.5596 | H8: note: all woods need fumigation - 10/9 DONE 10/13 | I8: LCL | J8: 1 | K8: 1 | L8: 1 | M8: n/a | N8: n/a | R8: =IF(VLOOKUP($A8,Items!$A$5:$J$1000,8,0)=0," ",VLOOKUP($A8,Items!$A$5:$J$1000,8,0)) | S8: =IF(VLOOKUP($A8,Items!$A$5:$J$1000,3,0)=0," ",VLOOKUP($A8,Items!$A$5:$J$1000,3,0)) | T8: =IF(VLOOKUP($A8,Items!$A$5:$J$1000,7,0)=0," ",VLOOKUP($A8,Items!$A$5:$J$1000,7,0)) | U8: =IF(VLOOKUP($A8,Items!$A$5:$J$1000,2,0)=0," ",VLOOKUP($A8,Items!$A$5:$J$1000,2,0)) | V8: =IF(VLOOKUP($A8,Items!$A$5:$J$1000,9,0)=0," ",VLOOKUP($A8,Items!$A$5:$J$1000,9,0)) | W8: =IF(VLOOKUP($A8,Items!$A$5:$J$1000,4,0)=0," ",VLOOKUP($A8,Items!$A$5:$J$1000,4,0)) | X8: =IF(VLOOKUP($A8,Items!$A$5:$J$1000,6,0)=0," ",VLOOKUP($A8,Items!$A$5:$J$1000,6,0)) | Y8: =IF(VLOOKUP($A8,Items!$A$5:$J$1000,5,0)=0," ",VLOOKUP($A8,Items!$A$5:$J$1000,5,0)) | AA8: =IF(VLOOKUP($A8,Wood!$A$5:$W$1000,16,0)=0," ",VLOOKUP($A8,Wood!$A$5:$W$1000,16,0)) | AB8: =IF(VLOOKUP($A8,Wood!$A$5:$W$1000,17,0)=0," ",VLOOKUP($A8,Wood!$A$5:$W$1000,17,0)) | AC8: =IF(VLOOKUP($A8,Wood!$A$5:$W$1000,18,0)=0," ",VLOOKUP($A8,Wood!$A$5:$W$1000,18,0)) | AD8: =IF(VLOOKUP($A8,Wood!$A$5:$W$1000,19,0)=0," ",VLOOKUP($A8,Wood!$A$5:$W$1000,19,0)) | AE8: =IF(VLOOKUP($A8,Wood!$A$5:$W$1000,20,0)=0," ",VLOOKUP($A8,Wood!$A$5:$W$1000,20,0)) | AF8: =IF(VLOOKUP($A8,Wood!$A$5:$W$1000,21,0)=0," ",VLOOKUP($A8,Wood!$A$5:$W$1000,21,0)) | AG8: =IF(VLOOKUP($A8,Wood!$A$5:$W$1000,22,0)=0," ",VLOOKUP($A8,Wood!$A$5:$W$1000,22,0)) | AH8: =IF(VLOOKUP($A8,Wood!$A$5:$W$1000,23,0)=0," ",VLOOKUP($A8,Wood!$A$5:$W$1000,23,0)) | AN8: 1 | AO8: n/a | AP8: n/a | AR8: 46297 | AT8: =NOW()-AR8 -> 17.617591 | AU8: =IFERROR(AVERAGE(J8:N8,AJ8:AP8),"n/a") -> 1
A9: 7891 | B9: 58300-SAUDI ARABIA | C9: HEATERS, CONTROLS, SPARE PARTS & WOODEN ACCESSORIES | D9: 1.15 | E9: =C9 -> HEATERS, CONTROLS, SPARE PARTS & WOODEN ACCESSORIES | J9: 1 | K9: 1 | L9: 1 | M9: n/a | N9: n/a | R9: =IF(VLOOKUP($A9,Items!$A$5:$J$1000,8,0)=0," ",VLOOKUP($A9,Items!$A$5:$J$1000,8,0)) | S9: =IF(VLOOKUP($A9,Items!$A$5:$J$1000,3,0)=0," ",VLOOKUP($A9,Items!$A$5:$J$1000,3,0)) | T9: =IF(VLOOKUP($A9,Items!$A$5:$J$1000,7,0)=0," ",VLOOKUP($A9,Items!$A$5:$J$1000,7,0)) | U9: =IF(VLOOKUP($A9,Items!$A$5:$J$1000,2,0)=0," ",VLOOKUP($A9,Items!$A$5:$J$1000,2,0)) | V9: =IF(VLOOKUP($A9,Items!$A$5:$J$1000,9,0)=0," ",VLOOKUP($A9,Items!$A$5:$J$1000,9,0)) | W9: =IF(VLOOKUP($A9,Items!$A$5:$J$1000,4,0)=0," ",VLOOKUP($A9,Items!$A$5:$J$1000,4,0)) | X9: =IF(VLOOKUP($A9,Items!$A$5:$J$1000,6,0)=0," ",VLOOKUP($A9,Items!$A$5:$J$1000,6,0)) | Y9: =IF(VLOOKUP($A9,Items!$A$5:$J$1000,5,0)=0," ",VLOOKUP($A9,Items!$A$5:$J$1000,5,0)) | AA9: =IF(VLOOKUP($A9,Wood!$A$5:$W$1000,16,0)=0," ",VLOOKUP($A9,Wood!$A$5:$W$1000,16,0)) | AB9: =IF(VLOOKUP($A9,Wood!$A$5:$W$1000,17,0)=0," ",VLOOKUP($A9,Wood!$A$5:$W$1000,17,0)) | AC9: =IF(VLOOKUP($A9,Wood!$A$5:$W$1000,18,0)=0," ",VLOOKUP($A9,Wood!$A$5:$W$1000,18,0)) | AD9: =IF(VLOOKUP($A9,Wood!$A$5:$W$1000,19,0)=0," ",VLOOKUP($A9,Wood!$A$5:$W$1000,19,0)) | AE9: =IF(VLOOKUP($A9,Wood!$A$5:$W$1000,20,0)=0," ",VLOOKUP($A9,Wood!$A$5:$W$1000,20,0)) | AF9: =IF(VLOOKUP($A9,Wood!$A$5:$W$1000,21,0)=0," ",VLOOKUP($A9,Wood!$A$5:$W$1000,21,0)) | AG9: =IF(VLOOKUP($A9,Wood!$A$5:$W$1000,22,0)=0," ",VLOOKUP($A9,Wood!$A$5:$W$1000,22,0)) | AH9: =IF(VLOOKUP($A9,Wood!$A$5:$W$1000,23,0)=0," ",VLOOKUP($A9,Wood!$A$5:$W$1000,23,0)) | AN9: 1 | AO9: n/a | AP9: n/a | AR9: 46297 | AT9: =NOW()-AR9 -> 17.617591 | AU9: =IFERROR(AVERAGE(J9:N9,AJ9:AP9),"n/a") -> 1
A10: 7292 | B10: 58300-SAUDI ARABIA | C10: CONTROLS & SPARE PARTS | D10: 0.27 | E10: =C10 -> CONTROLS & SPARE PARTS | J10: 1 | K10: 1 | L10: n/a | M10: n/a | N10: n/a | R10: =IF(VLOOKUP($A10,Items!$A$5:$J$1000,8,0)=0," ",VLOOKUP($A10,Items!$A$5:$J$1000,8,0)) | S10: =IF(VLOOKUP($A10,Items!$A$5:$J$1000,3,0)=0," ",VLOOKUP($A10,Items!$A$5:$J$1000,3,0)) | T10: =IF(VLOOKUP($A10,Items!$A$5:$J$1000,7,0)=0," ",VLOOKUP($A10,Items!$A$5:$J$1000,7,0)) | U10: =IF(VLOOKUP($A10,Items!$A$5:$J$1000,2,0)=0," ",VLOOKUP($A10,Items!$A$5:$J$1000,2,0)) | V10: =IF(VLOOKUP($A10,Items!$A$5:$J$1000,9,0)=0," ",VLOOKUP($A10,Items!$A$5:$J$1000,9,0)) | W10: =IF(VLOOKUP($A10,Items!$A$5:$J$1000,4,0)=0," ",VLOOKUP($A10,Items!$A$5:$J$1000,4,0)) | X10: =IF(VLOOKUP($A10,Items!$A$5:$J$1000,6,0)=0," ",VLOOKUP($A10,Items!$A$5:$J$1000,6,0)) | Y10: =IF(VLOOKUP($A10,Items!$A$5:$J$1000,5,0)=0," ",VLOOKUP($A10,Items!$A$5:$J$1000,5,0)) | AA10: =IF(VLOOKUP($A10,Wood!$A$5:$W$1000,16,0)=0," ",VLOOKUP($A10,Wood!$A$5:$W$1000,16,0)) | AB10: =IF(VLOOKUP($A10,Wood!$A$5:$W$1000,17,0)=0," ",VLOOKUP($A10,Wood!$A$5:$W$1000,17,0)) | AC10: =IF(VLOOKUP($A10,Wood!$A$5:$W$1000,18,0)=0," ",VLOOKUP($A10,Wood!$A$5:$W$1000,18,0)) | AD10: =IF(VLOOKUP($A10,Wood!$A$5:$W$1000,19,0)=0," ",VLOOKUP($A10,Wood!$A$5:$W$1000,19,0)) | AE10: =IF(VLOOKUP($A10,Wood!$A$5:$W$1000,20,0)=0," ",VLOOKUP($A10,Wood!$A$5:$W$1000,20,0)) | AF10: =IF(VLOOKUP($A10,Wood!$A$5:$W$1000,21,0)=0," ",VLOOKUP($A10,Wood!$A$5:$W$1000,21,0)) | AG10: =IF(VLOOKUP($A10,Wood!$A$5:$W$1000,22,0)=0," ",VLOOKUP($A10,Wood!$A$5:$W$1000,22,0)) | AH10: =IF(VLOOKUP($A10,Wood!$A$5:$W$1000,23,0)=0," ",VLOOKUP($A10,Wood!$A$5:$W$1000,23,0)) | AN10: 1 | AO10: n/a | AP10: n/a | AR10: 46157 | AT10: =NOW()-AR10 -> 157.61759 | AU10: =IFERROR(AVERAGE(J10:N10,AJ10:AP10),"n/a") -> 1
A11: 7829 | B11: 99100-AZERBAIJAN | C11: CONTROLS, HEATERS, SPARE PARTS, WOODEN ACCESSORIES, DOORS, SAUNA STONES & PANELS | D11: 42.08 | E11: =C11 -> CONTROLS, HEATERS, SPARE PARTS, WOODEN ACCESSORIES, DOORS, SAUNA STONES & PANELS | F11: =D11 -> 42.08 | H11: note: all woods need fumigation - 10/9 | J11: 1 | K11: 1 | L11: 1 | M11: 1 | N11: 1 | R11: =IF(VLOOKUP($A11,Items!$A$5:$J$1000,8,0)=0," ",VLOOKUP($A11,Items!$A$5:$J$1000,8,0)) -> 297 | S11: =IF(VLOOKUP($A11,Items!$A$5:$J$1000,3,0)=0," ",VLOOKUP($A11,Items!$A$5:$J$1000,3,0)) -> 151 | T11: =IF(VLOOKUP($A11,Items!$A$5:$J$1000,7,0)=0," ",VLOOKUP($A11,Items!$A$5:$J$1000,7,0)) -> 620 | U11: =IF(VLOOKUP($A11,Items!$A$5:$J$1000,2,0)=0," ",VLOOKUP($A11,Items!$A$5:$J$1000,2,0)) -> 40 | V11: =IF(VLOOKUP($A11,Items!$A$5:$J$1000,9,0)=0," ",VLOOKUP($A11,Items!$A$5:$J$1000,9,0)) | W11: =IF(VLOOKUP($A11,Items!$A$5:$J$1000,4,0)=0," ",VLOOKUP($A11,Items!$A$5:$J$1000,4,0)) -> 1860 | X11: =IF(VLOOKUP($A11,Items!$A$5:$J$1000,6,0)=0," ",VLOOKUP($A11,Items!$A$5:$J$1000,6,0)) -> 448 | Y11: =IF(VLOOKUP($A11,Items!$A$5:$J$1000,5,0)=0," ",VLOOKUP($A11,Items!$A$5:$J$1000,5,0)) | AA11: =IF(VLOOKUP($A11,Wood!$A$5:$W$1000,16,0)=0," ",VLOOKUP($A11,Wood!$A$5:$W$1000,16,0)) -> 0.1647 | AB11: =IF(VLOOKUP($A11,Wood!$A$5:$W$1000,17,0)=0," ",VLOOKUP($A11,Wood!$A$5:$W$1000,17,0)) -> 1.9845 | AC11: =IF(VLOOKUP($A11,Wood!$A$5:$W$1000,18,0)=0," ",VLOOKUP($A11,Wood!$A$5:$W$1000,18,0)) -> 0.7335 | AD11: =IF(VLOOKUP($A11,Wood!$A$5:$W$1000,19,0)=0," ",VLOOKUP($A11,Wood!$A$5:$W$1000,19,0)) -> 0.3493 | AE11: =IF(VLOOKUP($A11,Wood!$A$5:$W$1000,20,0)=0," ",VLOOKUP($A11,Wood!$A$5:$W$1000,20,0)) | AF11: =IF(VLOOKUP($A11,Wood!$A$5:$W$1000,21,0)=0," ",VLOOKUP($A11,Wood!$A$5:$W$1000,21,0)) | AG11: =IF(VLOOKUP($A11,Wood!$A$5:$W$1000,22,0)=0," ",VLOOKUP($A11,Wood!$A$5:$W$1000,22,0)) | AH11: =IF(VLOOKUP($A11,Wood!$A$5:$W$1000,23,0)=0," ",VLOOKUP($A11,Wood!$A$5:$W$1000,23,0)) | AN11: 1 | AO11: n/a | AP11: 1 | AR11: 46198 | AT11: =NOW()-AR11 -> 116.61759 | AU11: =IFERROR(AVERAGE(J11:N11,AJ11:AP11),"n/a") -> 1
A12: 8802 | B12: 51500-MAURITIUS | C12: 2 UNITS SAUNA ROOMS (2020MS-Cedar & 1919MS-Cedar) w/ complete set of accessories and heater & R-980 | D12: 2.07 | E12: =C12 -> 2 UNITS SAUNA ROOMS (2020MS-Cedar & 1919MS-Cedar) w/ complete set of accessories and heater & R-980 | F12: =D12 -> 2.07 | H12: note: all woods need fumigation - 10/16 | I12: LCL | J12: 1 | K12: 1 | L12: 1 | M12: n/a | N12: 1 | O12: 2 | R12: =IF(VLOOKUP($A12,Items!$A$5:$J$1000,8,0)=0," ",VLOOKUP($A12,Items!$A$5:$J$1000,8,0)) -> 11 | S12: =IF(VLOOKUP($A12,Items!$A$5:$J$1000,3,0)=0," ",VLOOKUP($A12,Items!$A$5:$J$1000,3,0)) -> 5 | T12: =IF(VLOOKUP($A12,Items!$A$5:$J$1000,7,0)=0," ",VLOOKUP($A12,Items!$A$5:$J$1000,7,0)) -> 24 | U12: =IF(VLOOKUP($A12,Items!$A$5:$J$1000,2,0)=0," ",VLOOKUP($A12,Items!$A$5:$J$1000,2,0)) | V12: =IF(VLOOKUP($A12,Items!$A$5:$J$1000,9,0)=0," ",VLOOKUP($A12,Items!$A$5:$J$1000,9,0)) -> 2 | W12: =IF(VLOOKUP($A12,Items!$A$5:$J$1000,4,0)=0," ",VLOOKUP($A12,Items!$A$5:$J$1000,4,0)) | X12: =IF(VLOOKUP($A12,Items!$A$5:$J$1000,6,0)=0," ",VLOOKUP($A12,Items!$A$5:$J$1000,6,0)) -> 3 | Y12: =IF(VLOOKUP($A12,Items!$A$5:$J$1000,5,0)=0," ",VLOOKUP($A12,Items!$A$5:$J$1000,5,0)) -> 36 | AA12: =IF(VLOOKUP($A12,Wood!$A$5:$W$1000,16,0)=0," ",VLOOKUP($A12,Wood!$A$5:$W$1000,16,0)) -> 0.3452 | AB12: =IF(VLOOKUP($A12,Wood!$A$5:$W$1000,17,0)=0," ",VLOOKUP($A12,Wood!$A$5:$W$1000,17,0)) -> 1.4385 | AC12: =IF(VLOOKUP($A12,Wood!$A$5:$W$1000,18,0)=0," ",VLOOKUP($A12,Wood!$A$5:$W$1000,18,0)) | AD12: =IF(VLOOKUP($A12,Wood!$A$5:$W$1000,19,0)=0," ",VLOOKUP($A12,Wood!$A$5:$W$1000,19,0)) | AE12: =IF(VLOOKUP($A12,Wood!$A$5:$W$1000,20,0)=0," ",VLOOKUP($A12,Wood!$A$5:$W$1000,20,0)) | AF12: =IF(VLOOKUP($A12,Wood!$A$5:$W$1000,21,0)=0," ",VLOOKUP($A12,Wood!$A$5:$W$1000,21,0)) | AG12: =IF(VLOOKUP($A12,Wood!$A$5:$W$1000,22,0)=0," ",VLOOKUP($A12,Wood!$A$5:$W$1000,22,0)) | AH12: =IF(VLOOKUP($A12,Wood!$A$5:$W$1000,23,0)=0," ",VLOOKUP($A12,Wood!$A$5:$W$1000,23,0)) | AN12: 1 | AO12: n/a | AP12: 1 | AR12: 46279 | AT12: =NOW()-AR12 -> 35.617591 | AU12: =IFERROR(AVERAGE(J12:N12,AJ12:AP12),"n/a") -> 1
A13: 8303 | B13: 13500-INDONESIA | C13: 1 UNIT SAUNA ROOM (1411LS-Cedar) w/ complete set of accessories and heater | D13: 0.14 | E13: =C13 -> 1 UNIT SAUNA ROOM (1411LS-Cedar) w/ complete set of accessories and heater | F13: =D13 -> 0.14 | H13: note: crate fumigation - 9/24 customized glass - P10861 9/28 | I13: LCL | J13: 1 | K13: 1 | L13: 1 | M13: n/a | N13: 1 | O13: 1 | R13: =IF(VLOOKUP($A13,Items!$A$5:$J$1000,8,0)=0," ",VLOOKUP($A13,Items!$A$5:$J$1000,8,0)) | S13: =IF(VLOOKUP($A13,Items!$A$5:$J$1000,3,0)=0," ",VLOOKUP($A13,Items!$A$5:$J$1000,3,0)) | T13: =IF(VLOOKUP($A13,Items!$A$5:$J$1000,7,0)=0," ",VLOOKUP($A13,Items!$A$5:$J$1000,7,0)) | U13: =IF(VLOOKUP($A13,Items!$A$5:$J$1000,2,0)=0," ",VLOOKUP($A13,Items!$A$5:$J$1000,2,0)) | V13: =IF(VLOOKUP($A13,Items!$A$5:$J$1000,9,0)=0," ",VLOOKUP($A13,Items!$A$5:$J$1000,9,0)) | W13: =IF(VLOOKUP($A13,Items!$A$5:$J$1000,4,0)=0," ",VLOOKUP($A13,Items!$A$5:$J$1000,4,0)) | X13: =IF(VLOOKUP($A13,Items!$A$5:$J$1000,6,0)=0," ",VLOOKUP($A13,Items!$A$5:$J$1000,6,0)) | Y13: =IF(VLOOKUP($A13,Items!$A$5:$J$1000,5,0)=0," ",VLOOKUP($A13,Items!$A$5:$J$1000,5,0)) | AA13: =IF(VLOOKUP($A13,Wood!$A$5:$W$1000,16,0)=0," ",VLOOKUP($A13,Wood!$A$5:$W$1000,16,0)) | AB13: =IF(VLOOKUP($A13,Wood!$A$5:$W$1000,17,0)=0," ",VLOOKUP($A13,Wood!$A$5:$W$1000,17,0)) | AC13: =IF(VLOOKUP($A13,Wood!$A$5:$W$1000,18,0)=0," ",VLOOKUP($A13,Wood!$A$5:$W$1000,18,0)) | AD13: =IF(VLOOKUP($A13,Wood!$A$5:$W$1000,19,0)=0," ",VLOOKUP($A13,Wood!$A$5:$W$1000,19,0)) | AE13: =IF(VLOOKUP($A13,Wood!$A$5:$W$1000,20,0)=0," ",VLOOKUP($A13,Wood!$A$5:$W$1000,20,0)) | AF13: =IF(VLOOKUP($A13,Wood!$A$5:$W$1000,21,0)=0," ",VLOOKUP($A13,Wood!$A$5:$W$1000,21,0)) | AG13: =IF(VLOOKUP($A13,Wood!$A$5:$W$1000,22,0)=0," ",VLOOKUP($A13,Wood!$A$5:$W$1000,22,0)) | AH13: =IF(VLOOKUP($A13,Wood!$A$5:$W$1000,23,0)=0," ",VLOOKUP($A13,Wood!$A$5:$W$1000,23,0)) | AN13: 1 | AO13: n/a | AP13: 1 | AR13: 46275 | AT13: =NOW()-AR13 -> 39.617591 | AU13: =IFERROR(AVERAGE(J13:N13,AJ13:AP13),"n/a") -> 1
A14: 9296 | B14: 15900- Makati |Techiron Resources Inc. | C14: HEATER GUARDS | D14: 0.05 | E14: =C14 -> HEATER GUARDS | F14: =D14 -> 0.05 | G14: 46314 | J14: n/a | K14: 0 | L14: 0 | M14: n/a | N14: n/a | P14: WEEK 43 | R14: =IF(VLOOKUP($A14,Items!$A$5:$J$1000,8,0)=0," ",VLOOKUP($A14,Items!$A$5:$J$1000,8,0)) | S14: =IF(VLOOKUP($A14,Items!$A$5:$J$1000,3,0)=0," ",VLOOKUP($A14,Items!$A$5:$J$1000,3,0)) | T14: =IF(VLOOKUP($A14,Items!$A$5:$J$1000,7,0)=0," ",VLOOKUP($A14,Items!$A$5:$J$1000,7,0)) -> 1 | U14: =IF(VLOOKUP($A14,Items!$A$5:$J$1000,2,0)=0," ",VLOOKUP($A14,Items!$A$5:$J$1000,2,0)) | V14: =IF(VLOOKUP($A14,Items!$A$5:$J$1000,9,0)=0," ",VLOOKUP($A14,Items!$A$5:$J$1000,9,0)) | W14: =IF(VLOOKUP($A14,Items!$A$5:$J$1000,4,0)=0," ",VLOOKUP($A14,Items!$A$5:$J$1000,4,0)) | X14: =IF(VLOOKUP($A14,Items!$A$5:$J$1000,6,0)=0," ",VLOOKUP($A14,Items!$A$5:$J$1000,6,0)) -> 1 | Y14: =IF(VLOOKUP($A14,Items!$A$5:$J$1000,5,0)=0," ",VLOOKUP($A14,Items!$A$5:$J$1000,5,0)) | AA14: =IF(VLOOKUP($A14,Wood!$A$5:$W$1000,16,0)=0," ",VLOOKUP($A14,Wood!$A$5:$W$1000,16,0)) | AB14: =IF(VLOOKUP($A14,Wood!$A$5:$W$1000,17,0)=0," ",VLOOKUP($A14,Wood!$A$5:$W$1000,17,0)) | AC14: =IF(VLOOKUP($A14,Wood!$A$5:$W$1000,18,0)=0," ",VLOOKUP($A14,Wood!$A$5:$W$1000,18,0)) | AD14: =IF(VLOOKUP($A14,Wood!$A$5:$W$1000,19,0)=0," ",VLOOKUP($A14,Wood!$A$5:$W$1000,19,0)) | AE14: =IF(VLOOKUP($A14,Wood!$A$5:$W$1000,20,0)=0," ",VLOOKUP($A14,Wood!$A$5:$W$1000,20,0)) | AF14: =IF(VLOOKUP($A14,Wood!$A$5:$W$1000,21,0)=0," ",VLOOKUP($A14,Wood!$A$5:$W$1000,21,0)) | AG14: =IF(VLOOKUP($A14,Wood!$A$5:$W$1000,22,0)=0," ",VLOOKUP($A14,Wood!$A$5:$W$1000,22,0)) | AH14: =IF(VLOOKUP($A14,Wood!$A$5:$W$1000,23,0)=0," ",VLOOKUP($A14,Wood!$A$5:$W$1000,23,0)) | AN14: n/a | AO14: n/a | AP14: n/a | AR14: 46310 | AS14: =IFERROR(G14-AR14,"") -> 4 | AT14: =NOW()-AR14 -> 4.6175914 | AU14: =IFERROR(AVERAGE(J14:N14,AJ14:AP14),"n/a") -> 0
A15: 9309 | B15: 43940-THAILAND | C15: HEATER | D15: 0.06403 | E15: =C15 -> HEATER | F15: =D15 -> 0.06403 | G15: 46314 | H15: 4X PACKING | I15: AIR | J15: n/a | K15: 0 | L15: n/a | M15: n/a | N15: n/a | P15: WEEK 43 | R15: =IF(VLOOKUP($A15,Items!$A$5:$J$1000,8,0)=0," ",VLOOKUP($A15,Items!$A$5:$J$1000,8,0)) | S15: =IF(VLOOKUP($A15,Items!$A$5:$J$1000,3,0)=0," ",VLOOKUP($A15,Items!$A$5:$J$1000,3,0)) -> 1 | T15: =IF(VLOOKUP($A15,Items!$A$5:$J$1000,7,0)=0," ",VLOOKUP($A15,Items!$A$5:$J$1000,7,0)) | U15: =IF(VLOOKUP($A15,Items!$A$5:$J$1000,2,0)=0," ",VLOOKUP($A15,Items!$A$5:$J$1000,2,0)) | V15: =IF(VLOOKUP($A15,Items!$A$5:$J$1000,9,0)=0," ",VLOOKUP($A15,Items!$A$5:$J$1000,9,0)) | W15: =IF(VLOOKUP($A15,Items!$A$5:$J$1000,4,0)=0," ",VLOOKUP($A15,Items!$A$5:$J$1000,4,0)) | X15: =IF(VLOOKUP($A15,Items!$A$5:$J$1000,6,0)=0," ",VLOOKUP($A15,Items!$A$5:$J$1000,6,0)) | Y15: =IF(VLOOKUP($A15,Items!$A$5:$J$1000,5,0)=0," ",VLOOKUP($A15,Items!$A$5:$J$1000,5,0)) | AA15: =IF(VLOOKUP($A15,Wood!$A$5:$W$1000,16,0)=0," ",VLOOKUP($A15,Wood!$A$5:$W$1000,16,0)) | AB15: =IF(VLOOKUP($A15,Wood!$A$5:$W$1000,17,0)=0," ",VLOOKUP($A15,Wood!$A$5:$W$1000,17,0)) | AC15: =IF(VLOOKUP($A15,Wood!$A$5:$W$1000,18,0)=0," ",VLOOKUP($A15,Wood!$A$5:$W$1000,18,0)) | AD15: =IF(VLOOKUP($A15,Wood!$A$5:$W$1000,19,0)=0," ",VLOOKUP($A15,Wood!$A$5:$W$1000,19,0)) | AE15: =IF(VLOOKUP($A15,Wood!$A$5:$W$1000,20,0)=0," ",VLOOKUP($A15,Wood!$A$5:$W$1000,20,0)) | AF15: =IF(VLOOKUP($A15,Wood!$A$5:$W$1000,21,0)=0," ",VLOOKUP($A15,Wood!$A$5:$W$1000,21,0)) | AG15: =IF(VLOOKUP($A15,Wood!$A$5:$W$1000,22,0)=0," ",VLOOKUP($A15,Wood!$A$5:$W$1000,22,0)) | AH15: =IF(VLOOKUP($A15,Wood!$A$5:$W$1000,23,0)=0," ",VLOOKUP($A15,Wood!$A$5:$W$1000,23,0)) | AN15: 0 | AO15: n/a | AP15: n/a | AR15: 46311 | AS15: =IFERROR(G15-AR15,"") -> 3 | AT15: =NOW()-AR15 -> 3.6175914 | AU15: =IFERROR(AVERAGE(J15:N15,AJ15:AP15),"n/a") -> 0
A16: 9117 | B16: 41700-CANADA BSAUNAS | C16: 2 UNITS SAUNA ROOMS (2222MD-Cedar & 1214RS-Cedar), WOODEN ACCESSORIES & DOORS | D16: 30.07 | E16: =C16 -> 2 UNITS SAUNA ROOMS (2222MD-Cedar & 1214RS-Cedar), WOODEN ACCESSORIES & DOORS | F16: =SUM(D16:D20) -> 83.268 | G16: 46315 | H16: note: all woods need fumigation - 10/16 | I16: 1X40HC | J16: n/a | K16: n/a | L16: 0 | M16: 0 | N16: 0 | O16: 2 | P16: WEEK 43 | R16: =IF(VLOOKUP($A16,Items!$A$5:$J$1000,8,0)=0," ",VLOOKUP($A16,Items!$A$5:$J$1000,8,0)) | S16: =IF(VLOOKUP($A16,Items!$A$5:$J$1000,3,0)=0," ",VLOOKUP($A16,Items!$A$5:$J$1000,3,0)) | T16: =IF(VLOOKUP($A16,Items!$A$5:$J$1000,7,0)=0," ",VLOOKUP($A16,Items!$A$5:$J$1000,7,0)) -> 540 | U16: =IF(VLOOKUP($A16,Items!$A$5:$J$1000,2,0)=0," ",VLOOKUP($A16,Items!$A$5:$J$1000,2,0)) -> 40 | V16: =IF(VLOOKUP($A16,Items!$A$5:$J$1000,9,0)=0," ",VLOOKUP($A16,Items!$A$5:$J$1000,9,0)) -> 2 | W16: =IF(VLOOKUP($A16,Items!$A$5:$J$1000,4,0)=0," ",VLOOKUP($A16,Items!$A$5:$J$1000,4,0)) | X16: =IF(VLOOKUP($A16,Items!$A$5:$J$1000,6,0)=0," ",VLOOKUP($A16,Items!$A$5:$J$1000,6,0)) | Y16: =IF(VLOOKUP($A16,Items!$A$5:$J$1000,5,0)=0," ",VLOOKUP($A16,Items!$A$5:$J$1000,5,0)) | AA16: =IF(VLOOKUP($A16,Wood!$A$5:$W$1000,16,0)=0," ",VLOOKUP($A16,Wood!$A$5:$W$1000,16,0)) -> 1.74 | AB16: =IF(VLOOKUP($A16,Wood!$A$5:$W$1000,17,0)=0," ",VLOOKUP($A16,Wood!$A$5:$W$1000,17,0)) -> 2.2528 | AC16: =IF(VLOOKUP($A16,Wood!$A$5:$W$1000,18,0)=0," ",VLOOKUP($A16,Wood!$A$5:$W$1000,18,0)) | AD16: =IF(VLOOKUP($A16,Wood!$A$5:$W$1000,19,0)=0," ",VLOOKUP($A16,Wood!$A$5:$W$1000,19,0)) | AE16: =IF(VLOOKUP($A16,Wood!$A$5:$W$1000,20,0)=0," ",VLOOKUP($A16,Wood!$A$5:$W$1000,20,0)) | AF16: =IF(VLOOKUP($A16,Wood!$A$5:$W$1000,21,0)=0," ",VLOOKUP($A16,Wood!$A$5:$W$1000,21,0)) | AG16: =IF(VLOOKUP($A16,Wood!$A$5:$W$1000,22,0)=0," ",VLOOKUP($A16,Wood!$A$5:$W$1000,22,0)) -> 0.0032 | AH16: =IF(VLOOKUP($A16,Wood!$A$5:$W$1000,23,0)=0," ",VLOOKUP($A16,Wood!$A$5:$W$1000,23,0)) | AN16: n/a | AO16: 0 | AP16: 0 | AR16: 46300 | AS16: =IFERROR(G16-AR16,"") -> 15 | AT16: =NOW()-AR16 -> 14.617591 | AU16: =IFERROR(AVERAGE(J16:N16,AJ16:AP16),"n/a") -> 0
A17: 8641 | B17: 41700-CANADA BSAUNAS BACKLOG | C17: WOODEN ACCESSORIES & DOORS | D17: 25.16 | E17: =C17 -> WOODEN ACCESSORIES & DOORS | G17: 46315 | J17: n/a | K17: n/a | L17: 0.56 | M17: 1 | N17: n/a | P17: WEEK 43 | R17: =IF(VLOOKUP($A17,Items!$A$5:$J$1000,8,0)=0," ",VLOOKUP($A17,Items!$A$5:$J$1000,8,0)) | S17: =IF(VLOOKUP($A17,Items!$A$5:$J$1000,3,0)=0," ",VLOOKUP($A17,Items!$A$5:$J$1000,3,0)) | T17: =IF(VLOOKUP($A17,Items!$A$5:$J$1000,7,0)=0," ",VLOOKUP($A17,Items!$A$5:$J$1000,7,0)) -> 4074 | U17: =IF(VLOOKUP($A17,Items!$A$5:$J$1000,2,0)=0," ",VLOOKUP($A17,Items!$A$5:$J$1000,2,0)) -> 10 | V17: =IF(VLOOKUP($A17,Items!$A$5:$J$1000,9,0)=0," ",VLOOKUP($A17,Items!$A$5:$J$1000,9,0)) | W17: =IF(VLOOKUP($A17,Items!$A$5:$J$1000,4,0)=0," ",VLOOKUP($A17,Items!$A$5:$J$1000,4,0)) | X17: =IF(VLOOKUP($A17,Items!$A$5:$J$1000,6,0)=0," ",VLOOKUP($A17,Items!$A$5:$J$1000,6,0)) | Y17: =IF(VLOOKUP($A17,Items!$A$5:$J$1000,5,0)=0," ",VLOOKUP($A17,Items!$A$5:$J$1000,5,0)) | AA17: =IF(VLOOKUP($A17,Wood!$A$5:$W$1000,16,0)=0," ",VLOOKUP($A17,Wood!$A$5:$W$1000,16,0)) -> 2.1492 | AB17: =IF(VLOOKUP($A17,Wood!$A$5:$W$1000,17,0)=0," ",VLOOKUP($A17,Wood!$A$5:$W$1000,17,0)) -> 9.05804 | AC17: =IF(VLOOKUP($A17,Wood!$A$5:$W$1000,18,0)=0," ",VLOOKUP($A17,Wood!$A$5:$W$1000,18,0)) -> 0.1008 | AD17: =IF(VLOOKUP($A17,Wood!$A$5:$W$1000,19,0)=0," ",VLOOKUP($A17,Wood!$A$5:$W$1000,19,0)) | AE17: =IF(VLOOKUP($A17,Wood!$A$5:$W$1000,20,0)=0," ",VLOOKUP($A17,Wood!$A$5:$W$1000,20,0)) | AF17: =IF(VLOOKUP($A17,Wood!$A$5:$W$1000,21,0)=0," ",VLOOKUP($A17,Wood!$A$5:$W$1000,21,0)) -> 4.19392 | AG17: =IF(VLOOKUP($A17,Wood!$A$5:$W$1000,22,0)=0," ",VLOOKUP($A17,Wood!$A$5:$W$1000,22,0)) | AH17: =IF(VLOOKUP($A17,Wood!$A$5:$W$1000,23,0)=0," ",VLOOKUP($A17,Wood!$A$5:$W$1000,23,0)) | AN17: n/a | AO17: 1 | AP17: n/a | AR17: 46267 | AS17: =IFERROR(G17-AR17,"") -> 48 | AT17: =NOW()-AR17 -> 47.617591 | AU17: =IFERROR(AVERAGE(J17:N17,AJ17:AP17),"n/a") -> 0.85333333
A18: 8102 | B18: 41700-CANADA BSAUNAS BACKLOG | C18: CORNER MOULDING | D18: 0.748 | E18: =C18 -> CORNER MOULDING | G18: 46315 | J18: n/a | K18: n/a | L18: n/a | M18: n/a | N18: 0.5 | P18: WEEK 43 | R18: =IF(VLOOKUP($A18,Items!$A$5:$J$1000,8,0)=0," ",VLOOKUP($A18,Items!$A$5:$J$1000,8,0)) | S18: =IF(VLOOKUP($A18,Items!$A$5:$J$1000,3,0)=0," ",VLOOKUP($A18,Items!$A$5:$J$1000,3,0)) | T18: =IF(VLOOKUP($A18,Items!$A$5:$J$1000,7,0)=0," ",VLOOKUP($A18,Items!$A$5:$J$1000,7,0)) | U18: =IF(VLOOKUP($A18,Items!$A$5:$J$1000,2,0)=0," ",VLOOKUP($A18,Items!$A$5:$J$1000,2,0)) | V18: =IF(VLOOKUP($A18,Items!$A$5:$J$1000,9,0)=0," ",VLOOKUP($A18,Items!$A$5:$J$1000,9,0)) | W18: =IF(VLOOKUP($A18,Items!$A$5:$J$1000,4,0)=0," ",VLOOKUP($A18,Items!$A$5:$J$1000,4,0)) | X18: =IF(VLOOKUP($A18,Items!$A$5:$J$1000,6,0)=0," ",VLOOKUP($A18,Items!$A$5:$J$1000,6,0)) -> 340 | Y18: =IF(VLOOKUP($A18,Items!$A$5:$J$1000,5,0)=0," ",VLOOKUP($A18,Items!$A$5:$J$1000,5,0)) | AA18: =IF(VLOOKUP($A18,Wood!$A$5:$W$1000,16,0)=0," ",VLOOKUP($A18,Wood!$A$5:$W$1000,16,0)) | AB18: =IF(VLOOKUP($A18,Wood!$A$5:$W$1000,17,0)=0," ",VLOOKUP($A18,Wood!$A$5:$W$1000,17,0)) | AC18: =IF(VLOOKUP($A18,Wood!$A$5:$W$1000,18,0)=0," ",VLOOKUP($A18,Wood!$A$5:$W$1000,18,0)) | AD18: =IF(VLOOKUP($A18,Wood!$A$5:$W$1000,19,0)=0," ",VLOOKUP($A18,Wood!$A$5:$W$1000,19,0)) | AE18: =IF(VLOOKUP($A18,Wood!$A$5:$W$1000,20,0)=0," ",VLOOKUP($A18,Wood!$A$5:$W$1000,20,0)) | AF18: =IF(VLOOKUP($A18,Wood!$A$5:$W$1000,21,0)=0," ",VLOOKUP($A18,Wood!$A$5:$W$1000,21,0)) | AG18: =IF(VLOOKUP($A18,Wood!$A$5:$W$1000,22,0)=0," ",VLOOKUP($A18,Wood!$A$5:$W$1000,22,0)) | AH18: =IF(VLOOKUP($A18,Wood!$A$5:$W$1000,23,0)=0," ",VLOOKUP($A18,Wood!$A$5:$W$1000,23,0)) | AN18: n/a | AO18: n/a | AP18: 0.5 | AR18: 46223 | AS18: =IFERROR(G18-AR18,"") -> 92 | AT18: =NOW()-AR18 -> 91.617591 | AU18: =IFERROR(AVERAGE(J18:N18,AJ18:AP18),"n/a") -> 0.5
A19: 5928 | B19: 41700-CANADA BSAUNAS BACKLOG | C19: DOORS | D19: 16.62 | E19: =C19 -> DOORS | J19: n/a | K19: n/a | L19: n/a | M19: 1 | N19: n/a | P19: WEEK 43 | R19: =IF(VLOOKUP($A19,Items!$A$5:$J$1000,8,0)=0," ",VLOOKUP($A19,Items!$A$5:$J$1000,8,0)) | S19: =IF(VLOOKUP($A19,Items!$A$5:$J$1000,3,0)=0," ",VLOOKUP($A19,Items!$A$5:$J$1000,3,0)) | T19: =IF(VLOOKUP($A19,Items!$A$5:$J$1000,7,0)=0," ",VLOOKUP($A19,Items!$A$5:$J$1000,7,0)) | U19: =IF(VLOOKUP($A19,Items!$A$5:$J$1000,2,0)=0," ",VLOOKUP($A19,Items!$A$5:$J$1000,2,0)) -> 70 | V19: =IF(VLOOKUP($A19,Items!$A$5:$J$1000,9,0)=0," ",VLOOKUP($A19,Items!$A$5:$J$1000,9,0)) | W19: =IF(VLOOKUP($A19,Items!$A$5:$J$1000,4,0)=0," ",VLOOKUP($A19,Items!$A$5:$J$1000,4,0)) | X19: =IF(VLOOKUP($A19,Items!$A$5:$J$1000,6,0)=0," ",VLOOKUP($A19,Items!$A$5:$J$1000,6,0)) | Y19: =IF(VLOOKUP($A19,Items!$A$5:$J$1000,5,0)=0," ",VLOOKUP($A19,Items!$A$5:$J$1000,5,0)) | AA19: =IF(VLOOKUP($A19,Wood!$A$5:$W$1000,16,0)=0," ",VLOOKUP($A19,Wood!$A$5:$W$1000,16,0)) -> 7.2538 | AB19: =IF(VLOOKUP($A19,Wood!$A$5:$W$1000,17,0)=0," ",VLOOKUP($A19,Wood!$A$5:$W$1000,17,0)) -> 0.6044 | AC19: =IF(VLOOKUP($A19,Wood!$A$5:$W$1000,18,0)=0," ",VLOOKUP($A19,Wood!$A$5:$W$1000,18,0)) | AD19: =IF(VLOOKUP($A19,Wood!$A$5:$W$1000,19,0)=0," ",VLOOKUP($A19,Wood!$A$5:$W$1000,19,0)) | AE19: =IF(VLOOKUP($A19,Wood!$A$5:$W$1000,20,0)=0," ",VLOOKUP($A19,Wood!$A$5:$W$1000,20,0)) | AF19: =IF(VLOOKUP($A19,Wood!$A$5:$W$1000,21,0)=0," ",VLOOKUP($A19,Wood!$A$5:$W$1000,21,0)) | AG19: =IF(VLOOKUP($A19,Wood!$A$5:$W$1000,22,0)=0," ",VLOOKUP($A19,Wood!$A$5:$W$1000,22,0)) -> 0.0008 | AH19: =IF(VLOOKUP($A19,Wood!$A$5:$W$1000,23,0)=0," ",VLOOKUP($A19,Wood!$A$5:$W$1000,23,0)) | AN19: n/a | AO19: 1 | AP19: n/a | AR19: 46090 | AT19: =NOW()-AR19 -> 224.61759 | AU19: =IFERROR(AVERAGE(J19:N19,AJ19:AP19),"n/a") -> 1
A20: 4781 | B20: 41700-CANADA BSAUNAS BACKLOG | C20: DOORS | D20: 10.67 | E20: =C20 -> DOORS | J20: n/a | K20: n/a | L20: n/a | M20: 0.9 | N20: n/a | P20: WEEK 43 | R20: =IF(VLOOKUP($A20,Items!$A$5:$J$1000,8,0)=0," ",VLOOKUP($A20,Items!$A$5:$J$1000,8,0)) | S20: =IF(VLOOKUP($A20,Items!$A$5:$J$1000,3,0)=0," ",VLOOKUP($A20,Items!$A$5:$J$1000,3,0)) | T20: =IF(VLOOKUP($A20,Items!$A$5:$J$1000,7,0)=0," ",VLOOKUP($A20,Items!$A$5:$J$1000,7,0)) | U20: =IF(VLOOKUP($A20,Items!$A$5:$J$1000,2,0)=0," ",VLOOKUP($A20,Items!$A$5:$J$1000,2,0)) -> 65 | V20: =IF(VLOOKUP($A20,Items!$A$5:$J$1000,9,0)=0," ",VLOOKUP($A20,Items!$A$5:$J$1000,9,0)) | W20: =IF(VLOOKUP($A20,Items!$A$5:$J$1000,4,0)=0," ",VLOOKUP($A20,Items!$A$5:$J$1000,4,0)) | X20: =IF(VLOOKUP($A20,Items!$A$5:$J$1000,6,0)=0," ",VLOOKUP($A20,Items!$A$5:$J$1000,6,0)) | Y20: =IF(VLOOKUP($A20,Items!$A$5:$J$1000,5,0)=0," ",VLOOKUP($A20,Items!$A$5:$J$1000,5,0)) | AA20: =IF(VLOOKUP($A20,Wood!$A$5:$W$1000,16,0)=0," ",VLOOKUP($A20,Wood!$A$5:$W$1000,16,0)) -> 3.61175 | AB20: =IF(VLOOKUP($A20,Wood!$A$5:$W$1000,17,0)=0," ",VLOOKUP($A20,Wood!$A$5:$W$1000,17,0)) -> 0.3411 | AC20: =IF(VLOOKUP($A20,Wood!$A$5:$W$1000,18,0)=0," ",VLOOKUP($A20,Wood!$A$5:$W$1000,18,0)) | AD20: =IF(VLOOKUP($A20,Wood!$A$5:$W$1000,19,0)=0," ",VLOOKUP($A20,Wood!$A$5:$W$1000,19,0)) | AE20: =IF(VLOOKUP($A20,Wood!$A$5:$W$1000,20,0)=0," ",VLOOKUP($A20,Wood!$A$5:$W$1000,20,0)) | AF20: =IF(VLOOKUP($A20,Wood!$A$5:$W$1000,21,0)=0," ",VLOOKUP($A20,Wood!$A$5:$W$1000,21,0)) | AG20: =IF(VLOOKUP($A20,Wood!$A$5:$W$1000,22,0)=0," ",VLOOKUP($A20,Wood!$A$5:$W$1000,22,0)) | AH20: =IF(VLOOKUP($A20,Wood!$A$5:$W$1000,23,0)=0," ",VLOOKUP($A20,Wood!$A$5:$W$1000,23,0)) | AN20: n/a | AO20: 1 | AP20: n/a | AR20: 45979 | AT20: =NOW()-AR20 -> 335.61759 | AU20: =IFERROR(AVERAGE(J20:N20,AJ20:AP20),"n/a") -> 0.95
A21: 9259 | B21: 27200-UAE | C21: SPARE PARTS & WOODEN ACCESSORIES | D21: 0.07 | E21: =C21 -> SPARE PARTS & WOODEN ACCESSORIES | F21: =D21 -> 0.07 | G21: 46316 | I21: AIR | J21: n/a | K21: 0 | L21: 0 | M21: n/a | N21: n/a | P21: WEEK 43 | R21: =IF(VLOOKUP($A21,Items!$A$5:$J$1000,8,0)=0," ",VLOOKUP($A21,Items!$A$5:$J$1000,8,0)) | S21: =IF(VLOOKUP($A21,Items!$A$5:$J$1000,3,0)=0," ",VLOOKUP($A21,Items!$A$5:$J$1000,3,0)) | T21: =IF(VLOOKUP($A21,Items!$A$5:$J$1000,7,0)=0," ",VLOOKUP($A21,Items!$A$5:$J$1000,7,0)) -> 20 | U21: =IF(VLOOKUP($A21,Items!$A$5:$J$1000,2,0)=0," ",VLOOKUP($A21,Items!$A$5:$J$1000,2,0)) | V21: =IF(VLOOKUP($A21,Items!$A$5:$J$1000,9,0)=0," ",VLOOKUP($A21,Items!$A$5:$J$1000,9,0)) | W21: =IF(VLOOKUP($A21,Items!$A$5:$J$1000,4,0)=0," ",VLOOKUP($A21,Items!$A$5:$J$1000,4,0)) | X21: =IF(VLOOKUP($A21,Items!$A$5:$J$1000,6,0)=0," ",VLOOKUP($A21,Items!$A$5:$J$1000,6,0)) -> 16 | Y21: =IF(VLOOKUP($A21,Items!$A$5:$J$1000,5,0)=0," ",VLOOKUP($A21,Items!$A$5:$J$1000,5,0)) | AA21: =IF(VLOOKUP($A21,Wood!$A$5:$W$1000,16,0)=0," ",VLOOKUP($A21,Wood!$A$5:$W$1000,16,0)) | AB21: =IF(VLOOKUP($A21,Wood!$A$5:$W$1000,17,0)=0," ",VLOOKUP($A21,Wood!$A$5:$W$1000,17,0)) | AC21: =IF(VLOOKUP($A21,Wood!$A$5:$W$1000,18,0)=0," ",VLOOKUP($A21,Wood!$A$5:$W$1000,18,0)) | AD21: =IF(VLOOKUP($A21,Wood!$A$5:$W$1000,19,0)=0," ",VLOOKUP($A21,Wood!$A$5:$W$1000,19,0)) | AE21: =IF(VLOOKUP($A21,Wood!$A$5:$W$1000,20,0)=0," ",VLOOKUP($A21,Wood!$A$5:$W$1000,20,0)) | AF21: =IF(VLOOKUP($A21,Wood!$A$5:$W$1000,21,0)=0," ",VLOOKUP($A21,Wood!$A$5:$W$1000,21,0)) | AG21: =IF(VLOOKUP($A21,Wood!$A$5:$W$1000,22,0)=0," ",VLOOKUP($A21,Wood!$A$5:$W$1000,22,0)) | AH21: =IF(VLOOKUP($A21,Wood!$A$5:$W$1000,23,0)=0," ",VLOOKUP($A21,Wood!$A$5:$W$1000,23,0)) | AN21: n/a | AO21: n/a | AP21: n/a | AR21: 46311 | AS21: =IFERROR(G21-AR21,"") -> 5 | AT21: =NOW()-AR21 -> 3.6175914 | AU21: =IFERROR(AVERAGE(J21:N21,AJ21:AP21),"n/a") -> 0
A22: 8765 | B22: 8200-AUSTRALIA | C22: 17 UNITS SAUNA ROOMS (1414RS-3sr Cedar, 1515RL-6sr Cedar, 1419RS-Cedar & 1520RL-7sr Cedar) w/ complete set of accessories and heater, SPARE PARTS, HEATERS, DOORS & WOODEN ACCESSORIES | D22: 58.86 | E22: =C22 -> 17 UNITS SAUNA ROOMS (1414RS-3sr Cedar, 1515RL-6sr Cedar, 1419RS-Cedar & 1520RL-7sr Cedar) w/ complete set of accessories and heater, SPARE PARTS, HEATERS, DOORS & WOODEN ACCESSORIES | F22: =SUM(D22:D23) -> 64.93 | G22: 46316 | H22: note: all woods need fumigation - 10/21 | I22: 1X40HC | J22: 0.821 | K22: 0.87 | L22: 0 | M22: 0 | N22: 0.083 | O22: 17 | P22: WEEK 43 | R22: =IF(VLOOKUP($A22,Items!$A$5:$J$1000,8,0)=0," ",VLOOKUP($A22,Items!$A$5:$J$1000,8,0)) -> 9 | S22: =IF(VLOOKUP($A22,Items!$A$5:$J$1000,3,0)=0," ",VLOOKUP($A22,Items!$A$5:$J$1000,3,0)) -> 75 | T22: =IF(VLOOKUP($A22,Items!$A$5:$J$1000,7,0)=0," ",VLOOKUP($A22,Items!$A$5:$J$1000,7,0)) -> 230 | U22: =IF(VLOOKUP($A22,Items!$A$5:$J$1000,2,0)=0," ",VLOOKUP($A22,Items!$A$5:$J$1000,2,0)) -> 4 | V22: =IF(VLOOKUP($A22,Items!$A$5:$J$1000,9,0)=0," ",VLOOKUP($A22,Items!$A$5:$J$1000,9,0)) -> 17 | W22: =IF(VLOOKUP($A22,Items!$A$5:$J$1000,4,0)=0," ",VLOOKUP($A22,Items!$A$5:$J$1000,4,0)) | X22: =IF(VLOOKUP($A22,Items!$A$5:$J$1000,6,0)=0," ",VLOOKUP($A22,Items!$A$5:$J$1000,6,0)) -> 229 | Y22: =IF(VLOOKUP($A22,Items!$A$5:$J$1000,5,0)=0," ",VLOOKUP($A22,Items!$A$5:$J$1000,5,0)) -> 101 | AA22: =IF(VLOOKUP($A22,Wood!$A$5:$W$1000,16,0)=0," ",VLOOKUP($A22,Wood!$A$5:$W$1000,16,0)) -> 3.39744 | AB22: =IF(VLOOKUP($A22,Wood!$A$5:$W$1000,17,0)=0," ",VLOOKUP($A22,Wood!$A$5:$W$1000,17,0)) -> 12.66294 | AC22: =IF(VLOOKUP($A22,Wood!$A$5:$W$1000,18,0)=0," ",VLOOKUP($A22,Wood!$A$5:$W$1000,18,0)) | AD22: =IF(VLOOKUP($A22,Wood!$A$5:$W$1000,19,0)=0," ",VLOOKUP($A22,Wood!$A$5:$W$1000,19,0)) | AE22: =IF(VLOOKUP($A22,Wood!$A$5:$W$1000,20,0)=0," ",VLOOKUP($A22,Wood!$A$5:$W$1000,20,0)) | AF22: =IF(VLOOKUP($A22,Wood!$A$5:$W$1000,21,0)=0," ",VLOOKUP($A22,Wood!$A$5:$W$1000,21,0)) | AG22: =IF(VLOOKUP($A22,Wood!$A$5:$W$1000,22,0)=0," ",VLOOKUP($A22,Wood!$A$5:$W$1000,22,0)) | AH22: =IF(VLOOKUP($A22,Wood!$A$5:$W$1000,23,0)=0," ",VLOOKUP($A22,Wood!$A$5:$W$1000,23,0)) | AN22: 0.87 | AO22: 0 | AP22: 1 | AR22: 46276 | AS22: =IFERROR(G22-AR22,"") -> 40 | AT22: =NOW()-AR22 -> 38.617591 | AU22: =IFERROR(AVERAGE(J22:N22,AJ22:AP22),"n/a") -> 0.4555
A23: 7919 | B23: 8200-AUSTRALIA | C23: 1 UNIT SAUNA ROOM (1620RL-Cedar) w/ complete set of accessories and heater, SAWO-20 & R-980 | D23: 6.07 | E23: =C23 -> 1 UNIT SAUNA ROOM (1620RL-Cedar) w/ complete set of accessories and heater, SAWO-20 & R-980 | J23: 1 | K23: 1 | L23: 1 | M23: n/a | N23: 1 | O23: 1 | P23: WEEK 43 | Q23: 2 | R23: =IF(VLOOKUP($A23,Items!$A$5:$J$1000,8,0)=0," ",VLOOKUP($A23,Items!$A$5:$J$1000,8,0)) | S23: =IF(VLOOKUP($A23,Items!$A$5:$J$1000,3,0)=0," ",VLOOKUP($A23,Items!$A$5:$J$1000,3,0)) -> 1 | T23: =IF(VLOOKUP($A23,Items!$A$5:$J$1000,7,0)=0," ",VLOOKUP($A23,Items!$A$5:$J$1000,7,0)) | U23: =IF(VLOOKUP($A23,Items!$A$5:$J$1000,2,0)=0," ",VLOOKUP($A23,Items!$A$5:$J$1000,2,0)) | V23: =IF(VLOOKUP($A23,Items!$A$5:$J$1000,9,0)=0," ",VLOOKUP($A23,Items!$A$5:$J$1000,9,0)) | W23: =IF(VLOOKUP($A23,Items!$A$5:$J$1000,4,0)=0," ",VLOOKUP($A23,Items!$A$5:$J$1000,4,0)) | X23: =IF(VLOOKUP($A23,Items!$A$5:$J$1000,6,0)=0," ",VLOOKUP($A23,Items!$A$5:$J$1000,6,0)) | Y23: =IF(VLOOKUP($A23,Items!$A$5:$J$1000,5,0)=0," ",VLOOKUP($A23,Items!$A$5:$J$1000,5,0)) | AA23: =IF(VLOOKUP($A23,Wood!$A$5:$W$1000,16,0)=0," ",VLOOKUP($A23,Wood!$A$5:$W$1000,16,0)) | AB23: =IF(VLOOKUP($A23,Wood!$A$5:$W$1000,17,0)=0," ",VLOOKUP($A23,Wood!$A$5:$W$1000,17,0)) | AC23: =IF(VLOOKUP($A23,Wood!$A$5:$W$1000,18,0)=0," ",VLOOKUP($A23,Wood!$A$5:$W$1000,18,0)) | AD23: =IF(VLOOKUP($A23,Wood!$A$5:$W$1000,19,0)=0," ",VLOOKUP($A23,Wood!$A$5:$W$1000,19,0)) | AE23: =IF(VLOOKUP($A23,Wood!$A$5:$W$1000,20,0)=0," ",VLOOKUP($A23,Wood!$A$5:$W$1000,20,0)) | AF23: =IF(VLOOKUP($A23,Wood!$A$5:$W$1000,21,0)=0," ",VLOOKUP($A23,Wood!$A$5:$W$1000,21,0)) | AG23: =IF(VLOOKUP($A23,Wood!$A$5:$W$1000,22,0)=0," ",VLOOKUP($A23,Wood!$A$5:$W$1000,22,0)) | AH23: =IF(VLOOKUP($A23,Wood!$A$5:$W$1000,23,0)=0," ",VLOOKUP($A23,Wood!$A$5:$W$1000,23,0)) | AN23: 1 | AO23: n/a | AP23: 1 | AR23: 46206 | AT23: =NOW()-AR23 -> 108.61759 | AU23: =IFERROR(AVERAGE(J23:N23,AJ23:AP23),"n/a") -> 1
A24: 9015 | B24: 15900- Mandaue City | Atty. Brando Raya | C24: 1 UNIT SAUNA ROOM (1430LL-Cedar) w/ complete set of accessories and heater | D24: 0.256 | E24: =C24 -> 1 UNIT SAUNA ROOM (1430LL-Cedar) w/ complete set of accessories and heater | F24: =D24 -> 0.256 | G24: 46323 | H24: PULL-OUT 10/28 | I24: LCL | J24: 0 | K24: 1 | L24: 0 | M24: n/a | N24: 0 | O24: 1 | P24: WEEK 44 | R24: =IF(VLOOKUP($A24,Items!$A$5:$J$1000,8,0)=0," ",VLOOKUP($A24,Items!$A$5:$J$1000,8,0)) -> 2 | S24: =IF(VLOOKUP($A24,Items!$A$5:$J$1000,3,0)=0," ",VLOOKUP($A24,Items!$A$5:$J$1000,3,0)) -> 1 | T24: =IF(VLOOKUP($A24,Items!$A$5:$J$1000,7,0)=0," ",VLOOKUP($A24,Items!$A$5:$J$1000,7,0)) -> 6 | U24: =IF(VLOOKUP($A24,Items!$A$5:$J$1000,2,0)=0," ",VLOOKUP($A24,Items!$A$5:$J$1000,2,0)) | V24: =IF(VLOOKUP($A24,Items!$A$5:$J$1000,9,0)=0," ",VLOOKUP($A24,Items!$A$5:$J$1000,9,0)) -> 1 | W24: =IF(VLOOKUP($A24,Items!$A$5:$J$1000,4,0)=0," ",VLOOKUP($A24,Items!$A$5:$J$1000,4,0)) | X24: =IF(VLOOKUP($A24,Items!$A$5:$J$1000,6,0)=0," ",VLOOKUP($A24,Items!$A$5:$J$1000,6,0)) -> 1 | Y24: =IF(VLOOKUP($A24,Items!$A$5:$J$1000,5,0)=0," ",VLOOKUP($A24,Items!$A$5:$J$1000,5,0)) -> 1 | AA24: =IF(VLOOKUP($A24,Wood!$A$5:$W$1000,16,0)=0," ",VLOOKUP($A24,Wood!$A$5:$W$1000,16,0)) -> 0.172 | AB24: =IF(VLOOKUP($A24,Wood!$A$5:$W$1000,17,0)=0," ",VLOOKUP($A24,Wood!$A$5:$W$1000,17,0)) -> 0.69256 | AC24: =IF(VLOOKUP($A24,Wood!$A$5:$W$1000,18,0)=0," ",VLOOKUP($A24,Wood!$A$5:$W$1000,18,0)) | AD24: =IF(VLOOKUP($A24,Wood!$A$5:$W$1000,19,0)=0," ",VLOOKUP($A24,Wood!$A$5:$W$1000,19,0)) | AE24: =IF(VLOOKUP($A24,Wood!$A$5:$W$1000,20,0)=0," ",VLOOKUP($A24,Wood!$A$5:$W$1000,20,0)) | AF24: =IF(VLOOKUP($A24,Wood!$A$5:$W$1000,21,0)=0," ",VLOOKUP($A24,Wood!$A$5:$W$1000,21,0)) | AG24: =IF(VLOOKUP($A24,Wood!$A$5:$W$1000,22,0)=0," ",VLOOKUP($A24,Wood!$A$5:$W$1000,22,0)) | AH24: =IF(VLOOKUP($A24,Wood!$A$5:$W$1000,23,0)=0," ",VLOOKUP($A24,Wood!$A$5:$W$1000,23,0)) | AN24: 1 | AO24: n/a | AP24: 0.4 | AR24: 46293 | AS24: =IFERROR(G24-AR24,"") -> 30 | AT24: =NOW()-AR24 -> 21.617591 | AU24: =IFERROR(AVERAGE(J24:N24,AJ24:AP24),"n/a") -> 0.4
A25: 9063 | B25: 15900- Borongan City | Kookie Lim Uy / 3K Salon And Spa | C25: 1 UNIT SAUNA ROOM (1414RS-Cedar) w/ complete set of accessories and heater | D25: 0.12 | E25: =C25 -> 1 UNIT SAUNA ROOM (1414RS-Cedar) w/ complete set of accessories and heater | F25: =D25 -> 0.12 | G25: 46323 | H25: PULL-OUT 10/28 | J25: 0 | K25: 1 | L25: 0 | M25: n/a | N25: 0 | O25: 1 | P25: WEEK 44 | R25: =IF(VLOOKUP($A25,Items!$A$5:$J$1000,8,0)=0," ",VLOOKUP($A25,Items!$A$5:$J$1000,8,0)) -> 2 | S25: =IF(VLOOKUP($A25,Items!$A$5:$J$1000,3,0)=0," ",VLOOKUP($A25,Items!$A$5:$J$1000,3,0)) -> 1 | T25: =IF(VLOOKUP($A25,Items!$A$5:$J$1000,7,0)=0," ",VLOOKUP($A25,Items!$A$5:$J$1000,7,0)) -> 5 | U25: =IF(VLOOKUP($A25,Items!$A$5:$J$1000,2,0)=0," ",VLOOKUP($A25,Items!$A$5:$J$1000,2,0)) | V25: =IF(VLOOKUP($A25,Items!$A$5:$J$1000,9,0)=0," ",VLOOKUP($A25,Items!$A$5:$J$1000,9,0)) -> 1 | W25: =IF(VLOOKUP($A25,Items!$A$5:$J$1000,4,0)=0," ",VLOOKUP($A25,Items!$A$5:$J$1000,4,0)) | X25: =IF(VLOOKUP($A25,Items!$A$5:$J$1000,6,0)=0," ",VLOOKUP($A25,Items!$A$5:$J$1000,6,0)) -> 1 | Y25: =IF(VLOOKUP($A25,Items!$A$5:$J$1000,5,0)=0," ",VLOOKUP($A25,Items!$A$5:$J$1000,5,0)) -> 1 | AA25: =IF(VLOOKUP($A25,Wood!$A$5:$W$1000,16,0)=0," ",VLOOKUP($A25,Wood!$A$5:$W$1000,16,0)) -> 0.172 | AB25: =IF(VLOOKUP($A25,Wood!$A$5:$W$1000,17,0)=0," ",VLOOKUP($A25,Wood!$A$5:$W$1000,17,0)) -> 0.69374 | AC25: =IF(VLOOKUP($A25,Wood!$A$5:$W$1000,18,0)=0," ",VLOOKUP($A25,Wood!$A$5:$W$1000,18,0)) | AD25: =IF(VLOOKUP($A25,Wood!$A$5:$W$1000,19,0)=0," ",VLOOKUP($A25,Wood!$A$5:$W$1000,19,0)) | AE25: =IF(VLOOKUP($A25,Wood!$A$5:$W$1000,20,0)=0," ",VLOOKUP($A25,Wood!$A$5:$W$1000,20,0)) | AF25: =IF(VLOOKUP($A25,Wood!$A$5:$W$1000,21,0)=0," ",VLOOKUP($A25,Wood!$A$5:$W$1000,21,0)) | AG25: =IF(VLOOKUP($A25,Wood!$A$5:$W$1000,22,0)=0," ",VLOOKUP($A25,Wood!$A$5:$W$1000,22,0)) | AH25: =IF(VLOOKUP($A25,Wood!$A$5:$W$1000,23,0)=0," ",VLOOKUP($A25,Wood!$A$5:$W$1000,23,0)) | AN25: 1 | AO25: n/a | AP25: 0.4 | AR25: 46295 | AS25: =IFERROR(G25-AR25,"") -> 28 | AT25: =NOW()-AR25 -> 19.617591 | AU25: =IFERROR(AVERAGE(J25:N25,AJ25:AP25),"n/a") -> 0.4
A26: 9131 | B26: 15900- Cagayan De Oro |Kevin Anthony Pilapil Lagumbay | C26: 1 UNIT SAUNA ROOM (1515RL-Cedar) w/ complete set of accessories and heater | D26: 0.12 | E26: =C26 -> 1 UNIT SAUNA ROOM (1515RL-Cedar) w/ complete set of accessories and heater | F26: =D26 -> 0.12 | G26: 46323 | H26: PULL-OUT 10/28 | J26: 0 | K26: 1 | L26: 0 | M26: n/a | N26: 0 | O26: 1 | P26: WEEK 44 | R26: =IF(VLOOKUP($A26,Items!$A$5:$J$1000,8,0)=0," ",VLOOKUP($A26,Items!$A$5:$J$1000,8,0)) -> 2 | S26: =IF(VLOOKUP($A26,Items!$A$5:$J$1000,3,0)=0," ",VLOOKUP($A26,Items!$A$5:$J$1000,3,0)) -> 1 | T26: =IF(VLOOKUP($A26,Items!$A$5:$J$1000,7,0)=0," ",VLOOKUP($A26,Items!$A$5:$J$1000,7,0)) -> 6 | U26: =IF(VLOOKUP($A26,Items!$A$5:$J$1000,2,0)=0," ",VLOOKUP($A26,Items!$A$5:$J$1000,2,0)) | V26: =IF(VLOOKUP($A26,Items!$A$5:$J$1000,9,0)=0," ",VLOOKUP($A26,Items!$A$5:$J$1000,9,0)) -> 1 | W26: =IF(VLOOKUP($A26,Items!$A$5:$J$1000,4,0)=0," ",VLOOKUP($A26,Items!$A$5:$J$1000,4,0)) | X26: =IF(VLOOKUP($A26,Items!$A$5:$J$1000,6,0)=0," ",VLOOKUP($A26,Items!$A$5:$J$1000,6,0)) -> 1 | Y26: =IF(VLOOKUP($A26,Items!$A$5:$J$1000,5,0)=0," ",VLOOKUP($A26,Items!$A$5:$J$1000,5,0)) -> 1 | AA26: =IF(VLOOKUP($A26,Wood!$A$5:$W$1000,16,0)=0," ",VLOOKUP($A26,Wood!$A$5:$W$1000,16,0)) -> 0.1732 | AB26: =IF(VLOOKUP($A26,Wood!$A$5:$W$1000,17,0)=0," ",VLOOKUP($A26,Wood!$A$5:$W$1000,17,0)) -> 0.69376 | AC26: =IF(VLOOKUP($A26,Wood!$A$5:$W$1000,18,0)=0," ",VLOOKUP($A26,Wood!$A$5:$W$1000,18,0)) | AD26: =IF(VLOOKUP($A26,Wood!$A$5:$W$1000,19,0)=0," ",VLOOKUP($A26,Wood!$A$5:$W$1000,19,0)) | AE26: =IF(VLOOKUP($A26,Wood!$A$5:$W$1000,20,0)=0," ",VLOOKUP($A26,Wood!$A$5:$W$1000,20,0)) | AF26: =IF(VLOOKUP($A26,Wood!$A$5:$W$1000,21,0)=0," ",VLOOKUP($A26,Wood!$A$5:$W$1000,21,0)) | AG26: =IF(VLOOKUP($A26,Wood!$A$5:$W$1000,22,0)=0," ",VLOOKUP($A26,Wood!$A$5:$W$1000,22,0)) | AH26: =IF(VLOOKUP($A26,Wood!$A$5:$W$1000,23,0)=0," ",VLOOKUP($A26,Wood!$A$5:$W$1000,23,0)) | AN26: 1 | AO26: n/a | AP26: 0.4 | AR26: 46300 | AS26: =IFERROR(G26-AR26,"") -> 23 | AT26: =NOW()-AR26 -> 14.617591 | AU26: =IFERROR(AVERAGE(J26:N26,AJ26:AP26),"n/a") -> 0.4
A27: 9228 | B27: 15900- Cebu City |Stephanie Sarmiento | C27: 1 UNIT SAUNA ROOM (1414RS-Cedar) w/ complete set of accessories and heater | D27: 0.16 | E27: =C27 -> 1 UNIT SAUNA ROOM (1414RS-Cedar) w/ complete set of accessories and heater | F27: =D27 -> 0.16 | G27: 46323 | H27: PULL-OUT 10/28 | J27: 0 | K27: 1 | L27: 0 | M27: n/a | N27: 0 | O27: 1 | P27: WEEK 44 | R27: =IF(VLOOKUP($A27,Items!$A$5:$J$1000,8,0)=0," ",VLOOKUP($A27,Items!$A$5:$J$1000,8,0)) -> 2 | S27: =IF(VLOOKUP($A27,Items!$A$5:$J$1000,3,0)=0," ",VLOOKUP($A27,Items!$A$5:$J$1000,3,0)) -> 1 | T27: =IF(VLOOKUP($A27,Items!$A$5:$J$1000,7,0)=0," ",VLOOKUP($A27,Items!$A$5:$J$1000,7,0)) -> 7 | U27: =IF(VLOOKUP($A27,Items!$A$5:$J$1000,2,0)=0," ",VLOOKUP($A27,Items!$A$5:$J$1000,2,0)) | V27: =IF(VLOOKUP($A27,Items!$A$5:$J$1000,9,0)=0," ",VLOOKUP($A27,Items!$A$5:$J$1000,9,0)) -> 1 | W27: =IF(VLOOKUP($A27,Items!$A$5:$J$1000,4,0)=0," ",VLOOKUP($A27,Items!$A$5:$J$1000,4,0)) | X27: =IF(VLOOKUP($A27,Items!$A$5:$J$1000,6,0)=0," ",VLOOKUP($A27,Items!$A$5:$J$1000,6,0)) -> 1 | Y27: =IF(VLOOKUP($A27,Items!$A$5:$J$1000,5,0)=0," ",VLOOKUP($A27,Items!$A$5:$J$1000,5,0)) -> 2 | AA27: =IF(VLOOKUP($A27,Wood!$A$5:$W$1000,16,0)=0," ",VLOOKUP($A27,Wood!$A$5:$W$1000,16,0)) | AB27: =IF(VLOOKUP($A27,Wood!$A$5:$W$1000,17,0)=0," ",VLOOKUP($A27,Wood!$A$5:$W$1000,17,0)) | AC27: =IF(VLOOKUP($A27,Wood!$A$5:$W$1000,18,0)=0," ",VLOOKUP($A27,Wood!$A$5:$W$1000,18,0)) | AD27: =IF(VLOOKUP($A27,Wood!$A$5:$W$1000,19,0)=0," ",VLOOKUP($A27,Wood!$A$5:$W$1000,19,0)) | AE27: =IF(VLOOKUP($A27,Wood!$A$5:$W$1000,20,0)=0," ",VLOOKUP($A27,Wood!$A$5:$W$1000,20,0)) | AF27: =IF(VLOOKUP($A27,Wood!$A$5:$W$1000,21,0)=0," ",VLOOKUP($A27,Wood!$A$5:$W$1000,21,0)) | AG27: =IF(VLOOKUP($A27,Wood!$A$5:$W$1000,22,0)=0," ",VLOOKUP($A27,Wood!$A$5:$W$1000,22,0)) | AH27: =IF(VLOOKUP($A27,Wood!$A$5:$W$1000,23,0)=0," ",VLOOKUP($A27,Wood!$A$5:$W$1000,23,0)) | AN27: 1 | AO27: n/a | AP27: 0.4 | AR27: 46307 | AS27: =IFERROR(G27-AR27,"") -> 16 | AT27: =NOW()-AR27 -> 7.6175914 | AU27: =IFERROR(AVERAGE(J27:N27,AJ27:AP27),"n/a") -> 0.4
